<?xml version="1.0"?>
<robot name="rmis" version="1.0">

  <!-- Material Definitions -->
  
  <!-- Dummy Link for KDL Parser -->
  <link name="root"/>
  
  <!-- Fixed Joint to Connect World to Base Link -->
  <joint name="root_to_base_joint" type="fixed">
    <parent link="root"/>
    <child link="base_link"/>
    <origin rpy="0.00000 0.00000 -0.00000" xyz="-0.15389 -0.00000 -0.00001"/>
    <dynamics damping="1.00000" friction="0.1"/>
  </joint>

  
  <!-- Sensors Section -->
  
  	<!-- Lidar -->
  <joint name="lidar_link_joint" type="fixed">
    <origin xyz="0.15210 0.54325 0.16884" rpy="0.0 0.0 0.0"/>
    <parent link="base_link"/>
    <child link="lidar_link"/>
  </joint>
  <link name="lidar_link">
    <inertial>
      <origin xyz="-1.54987 0.01466 -0.04121" rpy="0.0 0.0 0.0"/>
      <mass value="0.05000"/>
      <inertia ixx="0.05768" ixy="0.00012" ixz="-0.00062" iyy="0.02857" iyz="0.00006" izz="0.05022"/>
    </inertial>
    <visual name="lidar">
      <origin xyz="-0.15388 0.0 -0.00000" rpy="0.0 0.0 0.0"/>
      <geometry>
        <mesh filename="package://rmis/meshes/stl/TF_Luna.stl" scale="0.1 0.1 0.1"/>
      </geometry>
      <material name="black">
        <color rgba="0.0 0.0 0.0 1.0"/>
      </material>
    </visual>
    <collision name="lidar_collision">
      <origin xyz="-0.15388 0.0 -0.00001" rpy="0.0 0.0 0.0"/>
      <geometry>
        <mesh filename="package://rmis/meshes/stl/TF_Luna.stl" scale="0.1 0.1 0.1"/>
      </geometry>
    </collision>
  </link>
  <gazebo reference="lidar_link">
    <material>Gazebo/Black</material>
    <sensor name="tf_luna" type="ray">
      <pose>0.0 0.0 0.0 0.0 0.0 0.0</pose>
      <visualize>true</visualize>
      <update_rate>10</update_rate>
      <ray>
        <scan>
          <horizontal>
            <samples>100</samples>
            <resolution>0.01047</resolution>
            <min_angle>-0.52360</min_angle>
            <max_angle>0.52360</max_angle>
          </horizontal>
        </scan>
        <range>
          <min>0.2</min>
          <max>8.0</max>
          <resolution>0.01</resolution>
        </range>
      </ray>
      <plugin name="lidar_plugin" filename="libgazebo_ros_ray_sensor.so">
        <ros>
          <namespace>/rmis</namespace>
          <remapping>~/out:=lidar_scan</remapping>
        </ros>
        <frame_name>lidar_link</frame_name>
      </plugin>
    </sensor>
  </gazebo>

  	<!-- IMU -->
  <joint name="imu_link_joint" type="fixed">
    <origin xyz="0.21039 -0.34355 -1.01118" rpy="0.0 0.0 1.57080"/>
    <parent link="base_link"/>
    <child link="imu_link"/>
  </joint>
  <link name="imu_link">
    <inertial>
      <origin xyz="0.0 2.30103 0.0" rpy="0.0 0.0 0.0"/>
      <mass value="0.05000"/>
      <inertia ixx="0.03333" ixy="0.0" ixz="0.0" iyy="0.01817" iyz="0.0" izz="0.01817"/>
    </inertial>
    <visual name="imu">
      <origin xyz="0.0 0.23010 0.0" rpy="0.0 0.0 0.0"/>
      <geometry>
        <box size="0.06 0.2 0.2"/>
      </geometry>
      <material name="blue">
        <color rgba="0.0 0.0 1.0 1.0"/>
      </material>
    </visual>
    <collision name="imu_collision">
      <origin xyz="0.0 0.23010 0.0" rpy="0.0 0.0 0.0"/>
      <geometry>
        <box size="0.06 0.2 0.2"/>
      </geometry>
    </collision>
  </link>
	<gazebo reference="imu_link">
	  <sensor type="imu" name="imu_sensor">
	    <plugin name="imu_plugin" filename="libgazebo_ros_imu.so">
	      <ros>
		<namespace>/rmis</namespace>
		<remapping>imu:=imu/data</remapping>
	      </ros>
	    </plugin>
	  </sensor>
	</gazebo>
  
	<!-- Camera -->  
    <joint name="camera_link_joint" type="fixed">
    <origin xyz="-0.00027 0.51877 -0.01898" rpy="0.0 0.0 1.57080"/>
    <parent link="head_outer_link"/>
    <child link="camera_link"/>
  </joint>
  <link name="camera_link">
    <inertial>
      <inertia ixx="0.00002" ixy="-0.00000" ixz="-0.00000" iyy="0.00002" iyz="-0.00000" izz="0.00002"/>
      <origin rpy="0.00000 0.00000 0.00000" xyz="-0.03334 0.00356 -0.00558"/>
      <mass value="0.05000"/>
    </inertial>
    <visual name="camera">
      <origin rpy="-0.00000 -0.00000 -0.00000" xyz="-0.00333 0.00036 -0.00055"/>
      <geometry>
        <sphere radius="0.03000"/>
      </geometry>
    </visual>
  </link>
  <gazebo reference="camera_link">
    <material>Gazebo/Black</material>
    <sensor name="rasp_cam" type="camera">
      <pose>0.02942 0.0 0.0 -0.0 1.57080 0.0</pose>
      <camera>
        <horizontal_fov>1.57080</horizontal_fov>
        <image>
          <width>3280</width>
          <height>2464</height>
          <format>R8G8B8</format>
        </image>
        <clip>
          <near>0.01</near>
          <far>100.0</far>
        </clip>
      </camera>
      <update_rate>30</update_rate>
      <visualize>true</visualize>
      <plugin name="camera_plugin" filename="libgazebo_ros_camera.so">
        <ros>
          <namespace>/rmis</namespace>
          <remapping>~/out:=camera/image_raw</remapping>
        </ros>
        <frame_name>camera_link</frame_name>
      </plugin>
    </sensor>
  </gazebo>
  
  <!-- Base Link -->
  <link name="base_link">
    <collision name="base_collision">
      <origin rpy="0.00000 0.00000 -0.00000" xyz="-0.15389 -0.00000 -0.00001"/>
      <geometry>
        <mesh filename="package://rmis/meshes/stl/base.stl" scale="0.10000 0.10000 0.10000"/>
      </geometry>
    </collision>
    <inertial>
      <inertia ixx="3.80664" ixy="0.00010" ixz="-0.11562" iyy="2.86595" iyz="0.00147" izz="1.72824"/>
      <origin rpy="0.00000 0.00000 0.00000" xyz="-0.00284 -0.01176 0.03521"/>
      <mass value="0.05000"/>
    </inertial>
    <visual name="base">
      <origin rpy="0.00000 0.00000 0.00000" xyz="-0.15389 -0.00000 -0.00001"/>
      <geometry>
        <mesh filename="package://rmis/meshes/stl/base.stl" scale="0.10000 0.10000 0.10000"/>
      </geometry>
      <material name="grey">
        <color rgba="0.5 0.5 0.5 1.0"/>
      </material>      
    </visual>
  </link>
  <gazebo reference="base_link">
    <material>Gazebo/Grey</material>
  </gazebo>
  
  	<!-- Up Upper Body Section -->
  <joint name="u_upper_body_link_joint" type="revolute">
    <origin xyz="-0.00039 -0.01857 0.85581" rpy="0.0 0.0 0.0"/>
    <parent link="base_link"/>
    <child link="u_upper_body_link"/>
    <axis xyz="0.0 0.0 1.0"/>
    <dynamics damping="0.50000" friction="0.1"/>
    <limit lower="-3.14" upper="3.14" effort="1.2" velocity="1.0"/>
  </joint>
  <link name="u_upper_body_link">
    <inertial>
      <inertia ixx="0.00080" ixy="0.00000" ixz="0.00000" iyy="0.00080" iyz="0.00000" izz="0.00080"/>
      <origin rpy="0.00000 0.00000 0.00000" xyz="-0.00154 -0.01747 0.00000"/>
      <mass value="0.05000"/>
    </inertial>
    <visual name="u_upper_body">
      <origin rpy="0.00000 0.00000 1.57080" xyz="-0.00015 -0.00175 0.00000"/>
      <geometry>
        <sphere radius="0.02000"/>
      </geometry>
      <material name="grey">
        <color rgba="0.5 0.5 0.5 1.0"/>
      </material>      
    </visual>
  </link>
  <gazebo reference="u_upper_body_link">
    <material>Gazebo/Grey</material>
  </gazebo>

  <joint name="neck_link_joint" type="fixed">
    <origin xyz="0.29394 -0.10231 0.17455" rpy="0.0 0.0 0.0"/>
    <parent link="u_upper_body_link"/>
    <child link="neck_link"/>
  </joint>
  <link name="neck_link">
    <collision name="neck_collision">
      <origin rpy="0.00000 0.00000 -0.00000" xyz="-0.29410 0.00000 -0.04091"/>
      <geometry>
        <mesh filename="package://rmis/meshes/stl/neck_joint.stl" scale="0.10000 0.10000 0.10000"/>
      </geometry>
    </collision>
    <inertial>
      <inertia ixx="0.10411" ixy="-0.00000" ixz="0.02435" iyy="0.11152" iyz="0.00000" izz="0.04042"/>
      <origin rpy="0.00000 0.00000 0.00000" xyz="-2.94095 0.00000 -0.40906"/>
      <mass value="0.05000"/>
    </inertial>
    <visual name="neck">
      <origin rpy="0.00000 0.00000 -0.00000" xyz="-0.29410 0.00000 -0.04091"/>
      <geometry>
        <mesh filename="package://rmis/meshes/stl/neck_joint.stl" scale="0.10000 0.10000 0.10000"/>
      </geometry>
      <material name="grey"/>
    </visual>
  </link>
  <gazebo reference="neck_link">
    <material>Gazebo/Grey</material>
  </gazebo>
  
    <joint name="head_inner_link_joint" type="revolute">
    <origin xyz="-0.53928 0.10308 0.14213" rpy="-1.57080 -1.57080 1.57080"/>
    <parent link="neck_link"/>
    <child link="head_inner_link"/>
    <axis xyz="0.0 0.0 1.0"/>
    <dynamics damping="0.50000" friction="0.1"/>
    <limit lower="-0.4" upper="0.4" effort="1.2" velocity="1.0"/>
  </joint>
  <link name="head_inner_link">
    <inertial>
      <inertia ixx="0.18266" ixy="0.01279" ixz="0.00147" iyy="0.09287" iyz="0.00504" izz="0.14329"/>
      <origin rpy="0.00000 0.00000 0.00000" xyz="0.86758 -0.32559 -2.66080"/>
      <mass value="0.05000"/>
    </inertial>
    <visual name="head_inner">
      <origin rpy="1.57080 1.57080 1.57080" xyz="0.10230 0.02942 -0.18450"/>
      <geometry>
        <mesh filename="package://rmis/meshes/stl/head_link.stl" scale="0.10000 0.10000 0.10000"/>
      </geometry>
      <material name="grey"/>
    </visual>
  </link>
  <gazebo reference="head_inner_link">
    <material>Gazebo/Grey</material>
  </gazebo>

  <joint name="head_outer_link_joint" type="fixed">
    <origin xyz="0.24166 -0.01105 -0.24237" rpy="1.57080 1.57080 1.57080"/>
    <parent link="head_inner_link"/>
    <child link="head_outer_link"/>
  </joint>
  <link name="head_outer_link">
    <collision name="head_outer_collision">
      <origin rpy="-0.00000 0.00000 -0.00000" xyz="0.00000 0.00000 -0.00000"/>
      <geometry>
        <mesh filename="package://rmis/meshes/stl/head_joint.stl" scale="0.10000 0.10000 0.10000"/>
      </geometry>
    </collision>
    <inertial>
      <inertia ixx="0.35611" ixy="0.08645" ixz="0.03018" iyy="1.36268" iyz="-0.00299" izz="1.33173"/>
      <origin rpy="0.00000 0.00000 0.00000" xyz="0.00015 0.13850 -0.00540"/>
      <mass value="0.05000"/>
    </inertial>
    <visual name="head_outer">
      <origin rpy="0.00000 0.00000 -0.00000" xyz="0.00000 0.00000 0.00000"/>
      <geometry>
        <mesh filename="package://rmis/meshes/stl/head_joint.stl" scale="0.10000 0.10000 0.10000"/>
      </geometry>
      <material name="grey"/>
    </visual>
  </link>
  <gazebo reference="head_outer_link">
    <material>Gazebo/Grey</material>
  </gazebo>
  
  	<!-- Right Upper Body -->
  <joint name="r_upper_body_link_joint" type="revolute">
    <origin xyz="1.02542 -0.10845 0.50152" rpy="0.0 1.57080 0.0"/>
    <parent link="base_link"/>
    <child link="r_upper_body_link"/>
    <axis xyz="0.0 0.0 1.0"/>
    <dynamics damping="0.50000" friction="0.1"/>
    <limit lower="-2.0" upper="2.0" effort="1.2" velocity="1.0"/>
  </joint>
  <link name="r_upper_body_link">
    <inertial>
      <inertia ixx="0.00080" ixy="-0.00000" ixz="-0.00000" iyy="0.00080" iyz="0.00000" izz="0.00080"/>
      <origin rpy="0.00000 0.00000 0.00000" xyz="0.00000 0.00000 -0.00001"/>
      <mass value="0.05000"/>
    </inertial>
    <visual name="r_upper_body">
      <origin rpy="-1.57080 -0.00000 1.57080" xyz="0.00000 0.00000 -0.00000"/>
      <geometry>
        <sphere radius="0.02000"/>
      </geometry>
      <material name="grey"/>
    </visual>
  </link>
  <gazebo reference="r_upper_body_link">
    <material>Gazebo/Grey</material>
  </gazebo>
  
    <joint name="r_upper_shoulder_link_joint" type="fixed">
      <origin xyz="-0.00313 0.00023 0.15034" rpy="-1.57080 -1.57080 1.57080"/>
      <parent link="r_upper_body_link"/>
      <child link="r_upper_shoulder_link"/>
    </joint>
  <link name="r_upper_shoulder_link">
    <collision name="r_upper_shoulder_collision">
      <origin rpy="0.00000 0.00000 -0.00000" xyz="-0.03319 -0.00117 0.00022"/>
      <geometry>
        <mesh filename="package://rmis/meshes/stl/r_shoulder_joint.stl" scale="0.10000 0.10000 0.10000"/>
      </geometry>
    </collision>
    <inertial>
      <inertia ixx="0.07973" ixy="0.00003" ixz="0.00000" iyy="0.18690" iyz="0.00000" izz="0.23547"/>
      <origin rpy="0.00000 0.00000 0.00000" xyz="-0.33190 -0.01173 0.00218"/>
      <mass value="0.05000"/>
    </inertial>
    <visual name="r_upper_shoulder">
      <origin rpy="0.00000 0.00000 0.00000" xyz="-0.03319 -0.00117 0.00022"/>
      <geometry>
        <mesh filename="package://rmis/meshes/stl/r_shoulder_joint.stl" scale="0.10000 0.10000 0.10000"/>
      </geometry>
      <material name="grey"/>
    </visual>
  </link>
    <gazebo reference="r_upper_shoulder_link">
      <material>Gazebo/Grey</material>
    </gazebo>

  <joint name="r_lower_shoulder_upper_link_joint" type="revolute">
    <dynamics damping="0.50000"/>
    <limit lower="-1.57000" upper="0.00000" effort="1.20000" velocity="1.00000"/>
    <origin rpy="-1.57080 0.00000 0.00000" xyz="0.14724 0.25015 -0.00175"/>
    <parent link="r_upper_shoulder_link"/>
    <child link="r_lower_shoulder_upper_link"/>
    <axis xyz="0.00000 0.00000 1.00000"/>
  </joint>
  <link name="r_lower_shoulder_upper_link">
    <inertial>
      <inertia ixx="0.00080" ixy="-0.00000" ixz="-0.00000" iyy="0.00080" iyz="-0.00000" izz="0.00080"/>
      <origin rpy="0.00000 0.00000 0.00000" xyz="0.00000 -0.00000 0.00000"/>
      <mass value="0.05000"/>
    </inertial>
    <visual name="r_lower_shoulder_upper">
      <origin rpy="1.33478 -1.57080 0.23602" xyz="0.00000 -0.00000 0.00000"/>
      <geometry>
        <sphere radius="0.02000"/>
      </geometry>
      <material name="grey"/>
    </visual>
  </link>
    <gazebo reference="r_lower_shoulder_upper_link">
      <material>Gazebo/Grey</material>
    </gazebo>

    <joint name="r_lower_shoulder_link_joint" type="fixed">
      <origin rpy="1.57080 0.00000 0.00000" xyz="0.01117 0.47331 -0.27353"/>
      <parent link="r_lower_shoulder_upper_link"/>
      <child link="r_lower_shoulder_link"/>
    </joint>
  <link name="r_lower_shoulder_link">
    <collision name="r_lower_shoulder_collision">
      <origin rpy="-0.00000 -0.00000 -0.00000" xyz="-0.00000 -0.00000 0.12556"/>
      <geometry>
        <mesh filename="package://rmis/meshes/stl/r_shoulder_link.stl" scale="0.10000 0.10000 0.10000"/>
      </geometry>
    </collision>
    <inertial>
      <inertia ixx="0.39984" ixy="-0.00420" ixz="-0.00292" iyy="0.46703" iyz="0.02155" izz="0.10487"/>
      <origin rpy="0.00000 0.00000 0.00000" xyz="-0.24446 -0.09093 0.87699"/>
      <mass value="0.05000"/>
    </inertial>
    <visual name="r_lower_shoulder">
      <origin rpy="-0.00000 0.00000 0.00000" xyz="-0.00000 0.00000 0.12556"/>
      <geometry>
        <mesh filename="package://rmis/meshes/stl/r_shoulder_link.stl" scale="0.10000 0.10000 0.10000"/>
      </geometry>
      <material name="grey"/>
    </visual>
  </link>
    <gazebo reference="r_lower_shoulder_link">
      <material>Gazebo/Grey</material>
    </gazebo>

  <joint name="r_lower_shoulder_lower_link_joint" type="revolute">
    <dynamics damping="0.50000"/>
    <limit lower="-1.57000" upper="1.57000" effort="1.20000" velocity="1.00000"/>
    <origin rpy="-3.14159 -0.00000 3.14159" xyz="-0.00476 0.06341 -0.39192"/>
    <parent link="r_lower_shoulder_link"/>
    <child link="r_lower_shoulder_lower_link"/>
    <axis xyz="0.00000 0.00000 1.00000"/>
  </joint>
  <link name="r_lower_shoulder_lower_link">
    <inertial>
      <inertia ixx="0.00080" ixy="0.00000" ixz="0.00000" iyy="0.00080" iyz="-0.00000" izz="0.00080"/>
      <origin rpy="0.00000 0.00000 0.00000" xyz="0.00000 0.00000 -0.00000"/>
      <mass value="0.05000"/>
    </inertial>
    <visual name="r_lower_shoulder_lower">
      <origin rpy="3.14159 0.00000 1.57080" xyz="-0.00000 -0.00000 -0.00000"/>
      <geometry>
        <sphere radius="0.02000"/>
      </geometry>
      <material name="grey"/>
    </visual>
  </link>
    <gazebo reference="r_lower_shoulder_lower_link">
      <material>Gazebo/Grey</material>
    </gazebo>

  <joint name="r_upper_arm_link_joint" type="fixed">
    <origin rpy="-3.14159 0.00000 3.14159" xyz="0.15365 -0.04003 0.13018"/>
    <parent link="r_lower_shoulder_lower_link"/>
    <child link="r_upper_arm_link"/>
  </joint>
  <link name="r_upper_arm_link">
    <collision name="r_upper_arm_collision">
      <origin rpy="0.00000 -0.00000 -0.00000" xyz="0.15373 0.03945 -0.00418"/>
      <geometry>
        <mesh filename="package://rmis/meshes/stl/r_arm_joint.stl" scale="0.10000 0.10000 0.10000"/>
      </geometry>
    </collision>
    <inertial>
      <inertia ixx="0.23547" ixy="-0.00000" ixz="-0.00000" iyy="0.07973" iyz="0.00003" izz="0.18690"/>
      <origin rpy="0.00000 0.00000 0.00000" xyz="1.53731 0.39454 -0.04178"/>
      <mass value="0.05000"/>
    </inertial>
    <visual name="r_upper_arm">
      <origin rpy="0.00000 -0.00000 -0.00000" xyz="0.15373 0.03945 -0.00418"/>
      <geometry>
        <mesh filename="package://rmis/meshes/stl/r_arm_joint.stl" scale="0.10000 0.10000 0.10000"/>
      </geometry>
      <material name="grey"/>
    </visual>
  </link>
    <gazebo reference="r_upper_arm_link">
      <material>Gazebo/Grey</material>
    </gazebo>

    <joint name="r_lower_arm_upper_link_joint" type="revolute">
      <origin rpy="0.00000 1.57080 0.00000" xyz="0.42891 0.03944 -0.18506"/>
    <parent link="r_upper_arm_link"/>
    <child link="r_lower_arm_upper_link"/>
      <axis xyz="0.0 0.0 1.0"/>
      <dynamics damping="0.50000" friction="0.1"/>
      <limit lower="-1.57" upper="1.57" effort="1.2" velocity="1.0"/>
    </joint>
  <link name="r_lower_arm_upper_link">
    <inertial>
      <inertia ixx="0.00080" ixy="0.00000" ixz="-0.00000" iyy="0.00080" iyz="-0.00000" izz="0.00080"/>
      <origin rpy="0.00000 0.00000 0.00000" xyz="-0.00000 0.00000 -0.00001"/>
      <mass value="0.05000"/>
    </inertial>
    <visual name="r_lower_arm_upper">
      <origin rpy="-1.57080 0.00000 1.57080" xyz="-0.00000 0.00000 -0.00000"/>
      <geometry>
        <sphere radius="0.02000"/>
      </geometry>
      <material name="grey"/>
    </visual>
  </link>
    <gazebo reference="r_lower_arm_upper_link">
      <material>Gazebo/Grey</material>
    </gazebo>
    
    <joint name="r_lower_arm_link_joint" type="fixed">
      <origin rpy="-1.57080 -1.57080 1.57080" xyz="0.57212 0.03274 -0.28788"/>
      <parent link="r_lower_arm_upper_link"/>
      <child link="r_lower_arm_link"/>
    </joint>
  <link name="r_lower_arm_link">
    <collision name="r_lower_arm_collision">
      <origin rpy="-0.00000 0.00000 -0.00000" xyz="0.04329 0.00000 0.00000"/>
      <geometry>
        <mesh filename="package://rmis/meshes/stl/r_arm_link.stl" scale="0.10000 0.10000 0.10000"/>
      </geometry>
    </collision>
    <inertial>
      <inertia ixx="1.02059" ixy="0.01519" ixz="-0.00666" iyy="1.05629" iyz="0.04688" izz="0.16236"/>
      <origin rpy="0.00000 0.00000 0.00000" xyz="0.43294 0.00008 -0.00044"/>
      <mass value="0.05000"/>
    </inertial>
    <visual name="r_lower_arm">
      <origin rpy="-0.00000 0.00000 -0.00000" xyz="0.04329 0.00000 0.00000"/>
      <geometry>
        <mesh filename="package://rmis/meshes/stl/r_arm_link.stl" scale="0.10000 0.10000 0.10000"/>
      </geometry>
      <material name="grey"/>
    </visual>
  </link>
    <gazebo reference="r_lower_arm_link">
      <material>Gazebo/Grey</material>
    </gazebo>    

    <joint name="r_lower_arm_lower_link_joint" type="revolute">
      <origin rpy="-1.57080 -0.00000 0.00000" xyz="-0.00892 0.31225 -0.11501"/>
      <parent link="r_lower_arm_link"/>
      <child link="r_lower_arm_lower_link"/>
      <axis xyz="0.0 0.0 1.0"/>
      <dynamics damping="0.50000" friction="0.1"/>
      <limit lower="0.00000" upper="0.65000" effort="1.20000" velocity="1.00000"/> 
    </joint>
  <link name="r_lower_arm_lower_link">
    <inertial>
      <inertia ixx="0.00080" ixy="0.00000" ixz="0.00000" iyy="0.00080" iyz="0.00000" izz="0.00080"/>
      <origin rpy="0.00000 0.00000 0.00000" xyz="0.00002 -0.00003 -0.00000"/>
      <mass value="0.05000"/>
    </inertial>
    <visual name="r_lower_arm_lower">
      <origin rpy="-1.24662 -1.57080 2.81742" xyz="0.00000 -0.00000 -0.00000"/>
      <geometry>
        <sphere radius="0.02000"/>
      </geometry>
      <material name="grey"/>
    </visual>
  </link>
    <gazebo reference="r_lower_arm_lower_link">
      <material>Gazebo/Grey</material>
    </gazebo>

    <joint name="r_hand_link_joint" type="fixed">
      <origin rpy="1.57080 -0.00000 -0.00000" xyz="-0.09662 0.29431 -0.27653"/>
      <parent link="r_lower_arm_lower_link"/>
      <child link="r_hand_link"/>
    </joint>
  <link name="r_hand_link">
    <collision name="r_hand_collision">
      <origin rpy="0.00000 -0.00000 -0.00000" xyz="0.00010 -0.00004 0.00060"/>
      <geometry>
        <mesh filename="package://rmis/meshes/stl/r_hand_joint.stl" scale="0.10000 0.10000 0.10000"/>
      </geometry>
    </collision>
    <inertial>
      <inertia ixx="0.21883" ixy="-0.00005" ixz="0.00033" iyy="0.31074" iyz="0.05939" izz="0.16883"/>
      <origin rpy="0.00000 0.00000 0.00000" xyz="0.00003 0.00000 -0.00000"/>
      <mass value="0.05000"/>
    </inertial>
    <visual name="r_hand">
      <origin rpy="-0.00000 -0.00000 0.00000" xyz="0.00000 0.00000 -0.00001"/>
      <geometry>
        <mesh filename="package://rmis/meshes/stl/r_hand_joint.stl" scale="0.10000 0.10000 0.10000"/>
      </geometry>
      <material name="grey"/>
    </visual>
  </link>
    <gazebo reference="r_hand_link">
      <material>Gazebo/Grey</material>
    </gazebo>
   
  	<!-- Left Upper Body -->
  <joint name="l_upper_body_link_joint" type="revolute">
    <origin rpy="0.00000 -1.57080 0.00000" xyz="-1.02542 -0.10845 0.50152"/>
    <parent link="base_link"/>
    <child link="l_upper_body_link"/>
    <axis xyz="0.0 0.0 1.0"/>
    <dynamics damping="0.50000" friction="0.1"/>
    <limit lower="-2.0" upper="2.0" effort="1.2" velocity="1.0"/>
  </joint>
  <link name="l_upper_body_link">
    <inertial>
      <inertia ixx="0.00080" ixy="0.00000" ixz="-0.00000" iyy="0.00080" iyz="-0.00000" izz="0.00080"/>
      <origin rpy="0.00000 0.00000 0.00000" xyz="0.00000 0.00000 -0.00000"/>
      <mass value="0.05000"/>
    </inertial>
    <visual name="l_upper_body">
      <origin rpy="1.57080 0.00000 1.57080" xyz="-0.00000 0.00000 -0.00000"/>
      <geometry>
        <sphere radius="0.02000"/>
      </geometry>
      <material name="grey"/>
    </visual>
  </link>
  <gazebo reference="l_upper_body_link">
    <material>Gazebo/Grey</material>
  </gazebo>

    <joint name="l_upper_shoulder_link_joint" type="fixed">
      <origin rpy="1.64773 1.57080 1.64773" xyz="0.00314 0.00023 0.15035"/>
      <parent link="l_upper_body_link"/>
      <child link="l_upper_shoulder_link"/>
    </joint>
  <link name="l_upper_shoulder_link">
    <collision name="l_upper_shoulder_collision">
      <origin rpy="-0.00000 -0.00000 -0.00000" xyz="0.02125 -0.00108 -0.00165"/>
      <geometry>
        <mesh filename="package://rmis/meshes/stl/l_shoulder_joint.stl" scale="0.10000 0.10000 0.10000"/>
      </geometry>
    </collision>
    <inertial>
      <inertia ixx="0.07973" ixy="0.00003" ixz="0.00000" iyy="0.18690" iyz="-0.00000" izz="0.23547"/>
      <origin rpy="0.00000 0.00000 0.00000" xyz="0.21242 -0.01084 -0.01650"/>
      <mass value="0.05000"/>
    </inertial>
    <visual name="l_upper_shoulder">
      <origin rpy="-0.00000 0.00000 0.00000" xyz="0.02124 -0.00108 -0.00165"/>
      <geometry>
        <mesh filename="package://rmis/meshes/stl/l_shoulder_joint.stl" scale="0.10000 0.10000 0.10000"/>
      </geometry>
      <material name="grey"/>
    </visual>
  </link>
    <gazebo reference="l_upper_shoulder_link">
      <material>Gazebo/Grey</material>
    </gazebo>

    <joint name="l_lower_shoulder_upper_link_joint" type="revolute">
      <origin rpy="-1.57080 0.00000 -0.00000" xyz="-0.15786 0.25015 0.00000"/>
      <parent link="l_upper_shoulder_link"/>
      <child link="l_lower_shoulder_upper_link"/>
      <axis xyz="0.0 0.0 1.0"/>
      <dynamics damping="0.50000" friction="0.1"/>
      <limit lower="0.0" upper="1.57" effort="1.2" velocity="1.0"/>
    </joint>
  <link name="l_lower_shoulder_upper_link">
    <inertial>
      <inertia ixx="0.00080" ixy="0.00000" ixz="-0.00000" iyy="0.00080" iyz="-0.00000" izz="0.00080"/>
      <origin rpy="0.00000 0.00000 0.00000" xyz="0.00004 -0.00008 -0.00000"/>
      <mass value="0.05000"/>
    </inertial>
    <visual name="l_lower_shoulder_upper">
      <origin rpy="1.20089 -1.57080 0.36990" xyz="0.00000 -0.00000 -0.00000"/>
      <geometry>
        <sphere radius="0.02000"/>
      </geometry>
      <material name="grey"/>
    </visual>
  </link>
    <gazebo reference="l_lower_shoulder_upper_link">
      <material>Gazebo/Grey</material>
    </gazebo>

    <joint name="l_lower_shoulder_link_joint" type="fixed">
      <origin rpy="1.57080 -0.00000 -0.00000" xyz="0.01024 0.62216 -0.27345"/>
      <parent link="l_lower_shoulder_upper_link"/>
      <child link="l_lower_shoulder_link"/>
    </joint>
  <link name="l_lower_shoulder_link">
    <collision name="l_lower_shoulder_collision">
      <origin rpy="-0.00000 0.00000 -0.00000" xyz="0.00000 -0.00000 0.27292"/>
      <geometry>
        <mesh filename="package://rmis/meshes/stl/l_shoulder_link.stl" scale="0.10000 0.10000 0.10000"/>
      </geometry>
    </collision>
    <inertial>
      <inertia ixx="0.39919" ixy="-0.00420" ixz="-0.00291" iyy="0.46649" iyz="0.02087" izz="0.10478"/>
      <origin rpy="0.00000 0.00000 0.00000" xyz="-0.24312 -0.09091 2.35092"/>
      <mass value="0.05000"/>
    </inertial>
    <visual name="l_lower_shoulder">
      <origin rpy="-0.00000 0.00000 0.00000" xyz="0.00000 -0.00000 0.27291"/>
      <geometry>
        <mesh filename="package://rmis/meshes/stl/l_shoulder_link.stl" scale="0.10000 0.10000 0.10000"/>
      </geometry>
      <material name="grey"/>
    </visual>
  </link>
    <gazebo reference="l_lower_shoulder_link">
      <material>Gazebo/Grey</material>
    </gazebo>

    <joint name="l_lower_shoulder_lower_link_joint" type="revolute">
      <limit lower="-1.57000" upper="1.57000" effort="1.20000" velocity="1.00000"/>
      <origin rpy="-3.14159 -0.00000 3.14159" xyz="-0.00763 0.06271 -0.24482"/>
      <parent link="l_lower_shoulder_link"/>
      <child link="l_lower_shoulder_lower_link"/>
      <axis xyz="0.00000 0.00000 1.00000"/>
      <dynamics damping="0.50000" friction="0.1"/>
    </joint>
  <link name="l_lower_shoulder_lower_link">
    <inertial>
      <inertia ixx="0.00080" ixy="0.00000" ixz="0.00000" iyy="0.00080" iyz="0.00000" izz="0.00080"/>
      <origin rpy="0.00000 0.00000 0.00000" xyz="-0.00000 -0.00000 0.00000"/>
      <mass value="0.05000"/>
    </inertial>
    <visual name="l_lower_shoulder_lower">
      <origin rpy="3.14159 0.00000 1.57080" xyz="-0.00000 -0.00000 -0.00000"/>
      <geometry>
        <sphere radius="0.02000"/>
      </geometry>
      <material name="grey"/>
    </visual>
  </link>
    <gazebo reference="l_lower_shoulder_lower_link">
      <material>Gazebo/Grey</material>
    </gazebo>

    <joint name="l_upper_arm_link_joint" type="fixed">
      <origin rpy="3.14159 0.00000 1.57080" xyz="-0.15525 0.00109 0.04879"/>
      <parent link="l_lower_shoulder_lower_link"/>
     <child link="l_upper_arm_link"/>
    </joint>
  <link name="l_upper_arm_link">
    <collision name="l_upper_arm_collision">
      <origin rpy="-0.00000 -0.00000 -1.57080" xyz="0.00047 0.15536 -0.08502"/>
      <geometry>
        <mesh filename="package://rmis/meshes/stl/l_arm_joint.stl" scale="0.10000 0.10000 0.10000"/>
      </geometry>
    </collision>
    <inertial>
      <inertia ixx="0.23547" ixy="0.00000" ixz="-0.00000" iyy="0.07973" iyz="-0.00003" izz="0.18690"/>
      <origin rpy="0.00000 0.00000 0.00000" xyz="0.00474 1.55361 -0.85025"/>
      <mass value="0.05000"/>
    </inertial>
    <visual name="l_upper_arm">
      <origin rpy="-0.00000 0.00000 -1.57080" xyz="0.00047 0.15536 -0.08502"/>
      <geometry>
        <mesh filename="package://rmis/meshes/stl/l_arm_joint.stl" scale="0.10000 0.10000 0.10000"/>
      </geometry>
      <material name="grey"/>
    </visual>
  </link>
    <gazebo reference="l_upper_arm_link">
      <material>Gazebo/Grey</material>
    </gazebo>

    <joint name="l_lower_arm_upper_link_joint" type="revolute">
      <origin rpy="-1.57080 -1.57080 0.00000" xyz="0.00000 0.40875 -0.26539"/>
      <parent link="l_upper_arm_link"/>
      <child link="l_lower_arm_upper_link"/>
      <axis xyz="0.0 0.0 1.0"/>
      <dynamics damping="0.50000" friction="0.1"/>
      <limit lower="-1.57" upper="1.57" effort="1.2" velocity="1.0"/>
    </joint>
  <link name="l_lower_arm_upper_link">
    <inertial>
      <inertia ixx="0.00080" ixy="-0.00000" ixz="-0.00000" iyy="0.00080" iyz="-0.00000" izz="0.00080"/>
      <origin rpy="0.00000 0.00000 0.00000" xyz="0.00000 -0.00000 -0.00005"/>
      <mass value="0.05000"/>
    </inertial>
    <visual name="l_lower_arm_upper">
      <origin rpy="1.57080 0.00000 1.57080" xyz="0.00000 -0.00000 -0.00000"/>
      <geometry>
        <sphere radius="0.02000"/>
      </geometry>
      <material name="grey"/>
    </visual>
  </link>
    <gazebo reference="l_lower_arm_upper_link">
      <material>Gazebo/Grey</material>
    </gazebo>
    
    <joint name="l_lower_arm_link_joint" type="fixed">
      <origin rpy="1.57080 1.57080 1.57080" xyz="-0.51082 -0.04756 -0.25313"/>
      <parent link="l_lower_arm_upper_link"/>
      <child link="l_lower_arm_link"/>
    </joint>
  <link name="l_lower_arm_link">
    <collision name="l_lower_arm_collision">
      <origin rpy="-0.00000 -0.00000 0.00000" xyz="-0.02780 -0.00000 -0.03897"/>
      <geometry>
        <mesh filename="package://rmis/meshes/stl/l_arm_link.stl" scale="0.10000 0.10000 0.10000"/>
      </geometry>
    </collision>
    <inertial>
      <inertia ixx="0.94985" ixy="0.01403" ixz="-0.02205" iyy="0.96144" iyz="-0.03505" izz="0.14266"/>
      <origin rpy="0.00000 0.00000 0.00000" xyz="-0.27813 -0.00006 -0.39048"/>
      <mass value="0.05000"/>
    </inertial>
    <visual name="l_lower_arm">
      <origin rpy="-0.00000 0.00000 0.00000" xyz="-0.02780 0.00000 -0.03897"/>
      <geometry>
        <mesh filename="package://rmis/meshes/stl/l_arm_link.stl" scale="0.10000 0.10000 0.10000"/>
      </geometry>
      <material name="grey"/>
    </visual>
  </link>
    <gazebo reference="l_lower_arm_link">
      <material>Gazebo/Grey</material>
    </gazebo>    

    <joint name="l_lower_arm_lower_link_joint" type="revolute">
      <limit lower="0.00000" upper="0.65000" effort="1.20000" velocity="1.00000"/>
      <origin rpy="1.57080 -0.00000 0.00000" xyz="0.02708 -0.30471 -0.17737"/>
      <parent link="l_lower_arm_link"/>
      <child link="l_lower_arm_lower_link"/>
      <axis xyz="0.00000 0.00000 1.00000"/>
      <dynamics damping="0.50000" friction="0.1"/>
    </joint>
  <link name="l_lower_arm_lower_link">
    <inertial>
      <inertia ixx="0.00080" ixy="0.00000" ixz="-0.00000" iyy="0.00080" iyz="-0.00000" izz="0.00080"/>
      <origin rpy="0.00000 0.00000 0.00000" xyz="0.00005 0.00000 -0.00000"/>
      <mass value="0.05000"/>
    </inertial>
    <visual name="l_lower_arm_lower">
      <origin rpy="-1.20089 1.57080 0.36990" xyz="0.00000 -0.00000 -0.00000"/>
      <geometry>
        <sphere radius="0.02000"/>
      </geometry>
      <material name="grey"/>
    </visual>
  </link>
    <gazebo reference="l_lower_arm_lower_link">
      <material>Gazebo/Grey</material>
    </gazebo>

    <joint name="l_hand_link_joint" type="fixed">
      <origin rpy="-1.57080 0.00000 -0.00000" xyz="0.08578 -0.25941 -0.27318"/>
      <parent link="l_lower_arm_lower_link"/>
      <child link="l_hand_link"/>
    </joint>
  <link name="l_hand_link">
    <collision name="l_hand_collision">
      <origin rpy="0.00000 -0.00000 -0.00000" xyz="0.00000 -0.00000 -0.00000"/>
      <geometry>
        <mesh filename="package://rmis/meshes/stl/l_hand_joint.stl" scale="0.10000 0.10000 0.10000"/>
      </geometry>
    </collision>
    <inertial>
      <inertia ixx="0.21883" ixy="-0.00006" ixz="-0.00033" iyy="0.30895" iyz="-0.06146" izz="0.17061"/>
      <origin rpy="0.00000 0.00000 0.00000" xyz="0.14961 -0.00247 -0.33393"/>
      <mass value="0.05000"/>
    </inertial>
    <visual name="l_hand">
      <origin rpy="0.00000 -0.00000 0.00000" xyz="-0.00000 -0.00000 -0.00000"/>
      <geometry>
        <mesh filename="package://rmis/meshes/stl/l_hand_joint.stl" scale="0.10000 0.10000 0.10000"/>
      </geometry>
      <material name="grey"/>
    </visual>
  </link>
    <gazebo reference="l_hand_link">
      <material>Gazebo/Grey</material>
    </gazebo>  
  
  	<!-- Lower Body Section -->
  <joint name="lower_body_link_joint" type="fixed">
    <origin rpy="-0.00000 -0.00000 0.00000" xyz="-0.04942 -0.07242 -1.16532"/>
    <parent link="base_link"/>
    <child link="lower_body_link"/>
  </joint>
  <link name="lower_body_link">
    <collision name="lower_body_collision">
      <origin rpy="0.00000 0.00000 -0.00000" xyz="-0.07498 -0.00000 0.12347"/>
      <geometry>
        <mesh filename="package://rmis/meshes/stl/lower_body_link.stl" scale="0.10000 0.10000 0.10000"/>
      </geometry>
    </collision>
    <inertial>
      <inertia ixx="1.03498" ixy="-0.00427" ixz="-0.00418" iyy="0.30934" iyz="-0.00367" izz="1.06913"/>
      <origin rpy="0.00000 0.00000 0.00000" xyz="0.45951 -0.12902 0.92811"/>
      <mass value="0.05000"/>
    </inertial>
    <visual name="lower_body">
      <origin rpy="-0.00000 0.00000 -0.00000" xyz="-0.07498 0.00000 0.12347"/>
      <geometry>
        <mesh filename="package://rmis/meshes/stl/lower_body_link.stl" scale="0.10000 0.10000 0.10000"/>
      </geometry>
      <material name="grey"/>
    </visual>
  </link>
  <gazebo reference="lower_body_link">
    <material>Gazebo/Grey</material>
  </gazebo>  
  
  		<!-- Right Lower Body -->
  <joint name="r_lower_body_link_joint" type="revolute">
    <origin rpy="3.14159 -0.00000 3.14159" xyz="0.53339 -0.11124 -0.22114"/>
    <parent link="lower_body_link"/>
    <child link="r_lower_body_link"/>
    <axis xyz="0.0 0.0 1.0"/>
    <dynamics damping="0.50000" friction="0.1"/>
    <limit lower="-0.3" upper="0.3" effort="1.2" velocity="1.0"/>
  </joint>
  <link name="r_lower_body_link">
    <inertial>
      <inertia ixx="0.00080" ixy="-0.00000" ixz="-0.00000" iyy="0.00080" iyz="0.00000" izz="0.00080"/>
      <origin rpy="0.00000 0.00000 0.00000" xyz="0.00000 0.00000 0.00002"/>
      <mass value="0.05000"/>
    </inertial>
    <visual name="r_lower_body">
      <origin rpy="3.14159 0.00000 1.57080" xyz="0.00000 0.00000 0.00000"/>
      <geometry>
        <sphere radius="0.02000"/>
      </geometry>
      <material name="grey"/>
    </visual>
  </link>
  <gazebo reference="r_lower_body_link">
    <material>Gazebo/Grey</material>
  </gazebo>
  
    <joint name="r_upper_hip_link_joint" type="fixed">
    <origin rpy="3.14159 0.00000 3.14159" xyz="0.00270 0.13586 0.14958"/>
    <parent link="r_lower_body_link"/>
    <child link="r_upper_hip_link"/>
  </joint>
  <link name="r_upper_hip_link">
    <collision name="r_upper_hip_collision">
      <origin rpy="0.00000 0.00000 -0.00000" xyz="0.00000 -0.00000 -0.02804"/>
      <geometry>
        <mesh filename="package://rmis/meshes/stl/r_hip_link.stl" scale="0.10000 0.10000 0.10000"/>
      </geometry>
    </collision>
    <inertial>
      <inertia ixx="0.09294" ixy="0.00539" ixz="-0.01231" iyy="0.14374" iyz="-0.00179" izz="0.18306"/>
      <origin rpy="0.00000 0.00000 0.00000" xyz="0.07651 -0.22930 -0.09070"/>
      <mass value="0.05000"/>
    </inertial>
    <visual name="r_upper_hip">
      <origin rpy="0.00000 0.00000 0.00000" xyz="0.00000 -0.00000 -0.02805"/>
      <geometry>
        <mesh filename="package://rmis/meshes/stl/r_hip_link.stl" scale="0.10000 0.10000 0.10000"/>
      </geometry>
      <material name="grey"/>
    </visual>
  </link>
  <gazebo reference="r_upper_hip_link">
    <material>Gazebo/Grey</material>
  </gazebo>

  <joint name="r_lower_hip_link_joint" type="revolute">
    <limit lower="-0.65000" upper="0.00000" effort="1.20000" velocity="1.00000"/>
    <origin rpy="-1.57080 0.00000 -0.00000" xyz="0.09774 0.24708 -0.04110"/>
    <parent link="r_upper_hip_link"/>
    <child link="r_lower_hip_link"/>
    <axis xyz="0.0 0.0 1.0"/>
    <dynamics damping="0.50000" friction="0.1"/>
  </joint>
  <link name="r_lower_hip_link">
    <collision name="r_lower_hip_collision">
      <origin rpy="1.57080 0.00000 0.00000" xyz="-0.00049 0.16245 -0.28569"/>
      <geometry>
        <mesh filename="package://rmis/meshes/stl/r_hip_joint.stl" scale="0.10000 0.10000 0.10000"/>
      </geometry>
    </collision>
    <inertial>
      <inertia ixx="0.09070" ixy="-0.00001" ixz="0.03156" iyy="0.28217" iyz="0.00000" izz="0.22140"/>
      <origin rpy="0.00000 0.00000 0.00000" xyz="-0.00490 1.62450 -2.85692"/>
      <mass value="0.05000"/>
    </inertial>
    <visual name="r_lower_hip">
      <origin rpy="1.57080 -0.00000 0.00000" xyz="-0.00049 0.16245 -0.28569"/>
      <geometry>
        <mesh filename="package://rmis/meshes/stl/r_hip_joint.stl" scale="0.10000 0.10000 0.10000"/>
      </geometry>
      <material name="grey"/>
    </visual>
  </link>
  <gazebo reference="r_lower_hip_link">
    <material>Gazebo/Grey</material>
  </gazebo>
  
    <joint name="r_upper_leg_inner_link_joint" type="fixed">
      <origin rpy="1.57080 -0.00000 0.00000" xyz="-0.22671 0.44776 -0.24837"/>
      <parent link="r_lower_hip_link"/>
      <child link="r_upper_leg_inner_link"/>
    </joint>
  <link name="r_upper_leg_inner_link">
    <collision name="r_upper_leg_inner_collision">
      <origin rpy="-0.00000 0.00000 -0.00000" xyz="0.02992 0.00000 -0.03300"/>
      <geometry>
        <mesh filename="package://rmis/meshes/stl/r_upper_leg_link.stl" scale="0.10000 0.10000 0.10000"/>
      </geometry>
    </collision>
    <inertial>
      <inertia ixx="0.14329" ixy="0.00504" ixz="-0.00147" iyy="0.09287" iyz="-0.01279" izz="0.18266"/>
      <origin rpy="0.00000 0.00000 0.00000" xyz="1.11499 -0.15547 0.28985"/>
      <mass value="0.05000"/>
    </inertial>
    <visual name="r_upper_leg_inner">
      <origin rpy="-0.00000 0.00000 -0.00000" xyz="0.02992 -0.00000 -0.03300"/>
      <geometry>
        <mesh filename="package://rmis/meshes/stl/r_upper_leg_link.stl" scale="0.10000 0.10000 0.10000"/>
      </geometry>
      <material name="grey"/>
    </visual>
  </link>
    <gazebo reference="r_upper_leg_inner_link">
      <material>Gazebo/Grey</material>
    </gazebo>
    
<joint name="r_upper_leg_outer_link_joint" type="revolute">
    <origin rpy="-1.57079 -1.57080 1.57079" xyz="-0.15574 -0.10590 -0.00315"/>
    <parent link="r_upper_leg_inner_link"/>
    <child link="r_upper_leg_outer_link"/>
    <axis xyz="0.0 0.0 1.0"/>
    <dynamics damping="0.50000" friction="0.1"/>
    <limit lower="-1.57" upper="1.57" effort="1.2" velocity="1.0"/>
  </joint>
  <link name="r_upper_leg_outer_link">
    <collision name="r_upper_leg_outer_collision">
      <origin rpy="-1.57079 1.57080 -1.57080" xyz="-0.20411 0.00479 -0.21364"/>
      <geometry>
        <mesh filename="package://rmis/meshes/stl/r_upper_leg_joint.stl" scale="0.10000 0.10000 0.10000"/>
      </geometry>
    </collision>
    <inertial>
      <inertia ixx="0.28227" ixy="0.00029" ixz="-0.00019" iyy="0.09090" iyz="0.03170" izz="0.22130"/>
      <origin rpy="0.00000 0.00000 0.00000" xyz="-1.61459 0.05261 -2.83045"/>
      <mass value="0.05000"/>
    </inertial>
    <visual name="r_upper_leg_outer">
      <origin rpy="1.57080 1.57080 1.57080" xyz="-0.20411 0.00479 -0.21364"/>
      <geometry>
        <mesh filename="package://rmis/meshes/stl/r_upper_leg_joint.stl" scale="0.10000 0.10000 0.10000"/>
      </geometry>
      <material name="grey"/>
    </visual>
  </link>
  <gazebo reference="r_upper_leg_outer_link">
    <material>Gazebo/Grey</material>
  </gazebo>

  <joint name="r_lower_leg_inner_link_joint" type="fixed">
    <origin rpy="-1.57079 1.57080 -1.57080" xyz="-0.50982 0.00553 -0.28932"/>
    <parent link="r_upper_leg_outer_link"/>
    <child link="r_lower_leg_inner_link"/>
  </joint>
  <link name="r_lower_leg_inner_link">
    <collision name="r_lower_leg_inner_collision">
      <origin rpy="0.00000 -0.00000 -0.00000" xyz="-0.03171 -0.00166 -0.02979"/>
      <geometry>
        <mesh filename="package://rmis/meshes/stl/r_lower_leg_link.stl" scale="0.10000 0.10000 0.10000"/>
      </geometry>
    </collision>
    <inertial>
      <inertia ixx="0.36405" ixy="-0.00120" ixz="0.00013" iyy="0.09410" iyz="0.04544" izz="0.29049"/>
      <origin rpy="0.00000 0.00000 0.00000" xyz="-0.25026 -0.01220 -0.35379"/>
      <mass value="0.05000"/>
    </inertial>
    <visual name="r_lower_leg_inner">
      <origin rpy="-0.00000 0.00000 0.00000" xyz="-0.03165 -0.00166 -0.03008"/>
      <geometry>
        <mesh filename="package://rmis/meshes/stl/r_lower_leg_link.stl" scale="0.10000 0.10000 0.10000"/>
      </geometry>
      <material name="grey"/>
    </visual>
  </link>
  <gazebo reference="r_lower_leg_inner_link">
    <material>Gazebo/Grey</material>
  </gazebo>

  <joint name="r_lower_leg_outer_link_joint" type="revolute">
    <origin xyz="-0.28933 -0.00553 -0.15922" rpy="0.0 -1.57080 0.0"/>
    <parent link="r_lower_leg_inner_link"/>
    <child link="r_lower_leg_outer_link"/>
    <axis xyz="0.0 0.0 1.0"/>
    <dynamics damping="0.50000" friction="0.1"/>
    <limit lower="-1.57" upper="1.57" effort="1.2" velocity="1.0"/>
  </joint>
  <link name="r_lower_leg_outer_link">
    <collision name="r_lower_leg_outer_collision">
      <origin rpy="1.57080 1.57080 1.57080" xyz="-0.18126 0.00553 -0.25265"/>
      <geometry>
        <mesh filename="package://rmis/meshes/stl/r_lower_leg_joint.stl" scale="0.10000 0.10000 0.10000"/>
      </geometry>
    </collision>
    <inertial>
      <inertia ixx="0.23547" ixy="0.00000" ixz="-0.00000" iyy="0.07973" iyz="-0.00003" izz="0.18690"/>
      <origin rpy="0.00000 0.00000 0.00000" xyz="-1.81259 0.05530 -2.52645"/>
      <mass value="0.05000"/>
    </inertial>
    <visual name="r_lower_leg_outer">
      <origin rpy="1.57080 1.57080 1.57080" xyz="-0.18126 0.00553 -0.25265"/>
      <geometry>
        <mesh filename="package://rmis/meshes/stl/r_lower_leg_joint.stl" scale="0.10000 0.10000 0.10000"/>
      </geometry>
      <material name="grey"/>
    </visual>
  </link>
  <gazebo reference="r_lower_leg_outer_link">
    <material>Gazebo/Grey</material>
  </gazebo>

  <joint name="r_upper_ankle_link_joint" type="fixed">
    <origin xyz="-0.58812 0.00553 -0.28932" rpy="1.57080 1.57080 1.57080"/>
    <parent link="r_lower_leg_outer_link"/>
    <child link="r_upper_ankle_link"/>
  </joint>
  <link name="r_upper_ankle_link">
    <collision name="r_upper_ankle_collision">
      <origin rpy="0.00000 -0.00000 -0.00000" xyz="-0.03171 -0.00166 0.04755"/>
      <geometry>
        <mesh filename="package://rmis/meshes/stl/r_ankle_link.stl" scale="0.10000 0.10000 0.10000"/>
      </geometry>
    </collision>
    <inertial>
      <inertia ixx="0.36405" ixy="-0.00120" ixz="0.00013" iyy="0.09410" iyz="0.04544" izz="0.29049"/>
      <origin rpy="0.00000 0.00000 0.00000" xyz="-0.25087 -0.01220 0.42255"/>
      <mass value="0.05000"/>
    </inertial>
    <visual name="r_upper_ankle">
      <origin rpy="-0.00000 0.00000 0.00000" xyz="-0.03171 -0.00166 0.04755"/>
      <geometry>
        <mesh filename="package://rmis/meshes/stl/r_ankle_link.stl" scale="0.10000 0.10000 0.10000"/>
      </geometry>
      <material name="grey"/>
    </visual>
  </link>
  <gazebo reference="r_upper_ankle_link">
    <material>Gazebo/Grey</material>
  </gazebo>
  
  <joint name="r_lower_ankle_link_joint" type="revolute">
    <origin xyz="-0.28932 -0.00553 -0.08191" rpy="0.0 -1.57080 0.0"/>
    <parent link="r_upper_ankle_link"/>
    <child link="r_lower_ankle_link"/>
    <axis xyz="0.0 0.0 1.0"/>
    <dynamics damping="0.50000" friction="0.1"/>
    <limit lower="-0.65" upper="0.3" effort="1.2" velocity="1.0"/>
  </joint>
  <link name="r_lower_ankle_link">
    <collision name="r_lower_ankle_collision">
      <origin rpy="0.00000 1.57080 0.00000" xyz="-0.18122 0.00553 -0.25264"/>
      <geometry>
        <mesh filename="package://rmis/meshes/stl/r_ankle_joint.stl" scale="0.10000 0.10000 0.10000"/>
      </geometry>
    </collision>
    <inertial>
      <inertia ixx="0.23547" ixy="0.00000" ixz="-0.00000" iyy="0.07973" iyz="-0.00003" izz="0.18690"/>
      <origin rpy="0.00000 0.00000 0.00000" xyz="-1.81224 0.05529 -2.52645"/>
      <mass value="0.05000"/>
    </inertial>
    <visual name="r_lower_ankle">
      <origin rpy="1.44644 1.57080 1.44644" xyz="-0.18123 0.00553 -0.25265"/>
      <geometry>
        <mesh filename="package://rmis/meshes/stl/r_ankle_joint.stl" scale="0.10000 0.10000 0.10000"/>
      </geometry>
      <material name="grey"/>
    </visual>
  </link>
  <gazebo reference="r_lower_ankle_link">
    <material>Gazebo/Grey</material>
  </gazebo>
   
  <joint name="r_feet_link_joint" type="fixed">
    <origin xyz="-0.29184 0.16032 -0.38614" rpy="1.57080 1.57080 1.57080"/>
    <parent link="r_lower_ankle_link"/>
    <child link="r_feet_link"/>
  </joint>
  <link name="r_feet_link">
    <collision name="r_feet_collision">
      <origin rpy="0.00000 0.00000 -0.00000" xyz="-0.07451 0.00000 0.11245"/>
      <geometry>
        <mesh filename="package://rmis/meshes/stl/r_feet_link.stl" scale="0.10000 0.10000 0.10000"/>
      </geometry>
    </collision>
    <inertial>
      <inertia ixx="0.37179" ixy="-0.00718" ixz="-0.00237" iyy="0.56463" iyz="0.00152" izz="0.80038"/>
      <origin rpy="0.00000 0.00000 0.00000" xyz="-0.74506 -0.00000 1.06002"/>
      <mass value="0.05000"/>
    </inertial>
    <visual name="r_feet">
      <origin rpy="-0.00000 0.00000 0.00000" xyz="-0.07451 0.00000 0.11244"/>
      <geometry>
        <mesh filename="package://rmis/meshes/stl/r_feet_link.stl" scale="0.10000 0.10000 0.10000"/>
      </geometry>
      <material name="grey"/>
    </visual>
  </link>
  <gazebo reference="r_feet_link">
    <material>Gazebo/Grey</material>
  </gazebo>   
  
  		<!-- Left Lower Body -->
  <joint name="l_lower_body_link_joint" type="revolute">
    <origin xyz="-0.43474 -0.11124 -0.22114" rpy="3.14159 0.0 3.14159"/>
    <parent link="lower_body_link"/>
    <child link="l_lower_body_link"/>
    <axis xyz="0.0 0.0 1.0"/>
    <dynamics damping="0.50000" friction="0.1"/>
    <limit lower="-0.3" upper="0.3" effort="1.2" velocity="1.0"/>
  </joint>
  <link name="l_lower_body_link">
    <inertial>
      <inertia ixx="0.00080" ixy="0.00000" ixz="-0.00000" iyy="0.00080" iyz="-0.00000" izz="0.00080"/>
      <origin rpy="0.00000 0.00000 0.00000" xyz="0.00000 0.00000 0.00000"/>
      <mass value="0.05000"/>
    </inertial>
    <visual name="l_lower_body">
      <origin rpy="3.14159 0.00000 1.57080" xyz="0.00000 0.00000 0.00000"/>
      <geometry>
        <sphere radius="0.02000"/>
      </geometry>
      <material name="grey"/>
    </visual>
  </link>
  <gazebo reference="l_lower_body_link">
    <material>Gazebo/Grey</material>
  </gazebo>
  
  <joint name="l_upper_hip_link_joint" type="fixed">
    <origin xyz="-0.08125 0.19501 0.16258" rpy="-3.14159 0.0 3.14159"/>
    <parent link="l_lower_body_link"/>
    <child link="l_upper_hip_link"/>
  </joint>
  <link name="l_upper_hip_link">
    <collision name="l_upper_hip_collision">
      <origin rpy="-0.00000 -0.00000 -0.00000" xyz="-0.07415 0.00000 -0.05783"/>
      <geometry>
        <mesh filename="package://rmis/meshes/stl/l_hip_link.stl" scale="0.10000 0.10000 0.10000"/>
      </geometry>
    </collision>
    <inertial>
      <inertia ixx="0.09287" ixy="-0.00504" ixz="-0.01279" iyy="0.14329" iyz="0.00147" izz="0.18266"/>
      <origin rpy="0.00000 0.00000 0.00000" xyz="-0.89692 -0.81581 0.04150"/>
      <mass value="0.05000"/>
    </inertial>
    <visual name="l_upper_hip">
      <origin rpy="0.00000 0.00000 0.00000" xyz="-0.07415 0.00000 -0.05783"/>
      <geometry>
        <mesh filename="package://rmis/meshes/stl/l_hip_link.stl" scale="0.10000 0.10000 0.10000"/>
      </geometry>
      <material name="grey"/>
    </visual>
  </link>
  <gazebo reference="l_upper_hip_link">
    <material>Gazebo/Grey</material>
  </gazebo>

  <joint name="l_lower_hip_link_joint" type="revolute">
    <origin xyz="-0.17610 0.18793 -0.02809" rpy="-1.57080 0.0 0.0"/>
    <parent link="l_upper_hip_link"/>
    <child link="l_lower_hip_link"/>
    <axis xyz="0.0 0.0 1.0"/>
    <dynamics damping="0.50000" friction="0.1"/>
    <limit lower="0.0" upper="0.65" effort="1.2" velocity="1.0"/>
  </joint>
  <link name="l_lower_hip_link">
    <collision name="l_lower_hip_collision">
      <origin rpy="1.57080 0.00000 -0.00000" xyz="0.00102 0.20500 -0.21627"/>
      <geometry>
        <mesh filename="package://rmis/meshes/stl/l_hip_joint.stl" scale="0.10000 0.10000 0.10000"/>
      </geometry>
    </collision>
    <inertial>
      <inertia ixx="0.09091" ixy="0.00004" ixz="0.03172" iyy="0.28233" iyz="-0.00003" izz="0.22135"/>
      <origin rpy="0.00000 0.00000 0.00000" xyz="0.01024 2.04998 -2.16272"/>
      <mass value="0.05000"/>
    </inertial>
    <visual name="l_lower_hip">
      <origin rpy="1.57080 0.00000 -0.00000" xyz="0.00102 0.20500 -0.21627"/>
      <geometry>
        <mesh filename="package://rmis/meshes/stl/l_hip_joint.stl" scale="0.10000 0.10000 0.10000"/>
      </geometry>
      <material name="grey"/>
    </visual>
  </link>
  <gazebo reference="l_lower_hip_link">
    <material>Gazebo/Grey</material>
  </gazebo>

  <joint name="l_upper_leg_inner_link_joint" type="fixed">
    <origin xyz="0.23325 0.42698 -0.25846" rpy="1.57080 0.0 0.0"/>
    <parent link="l_lower_hip_link"/>
    <child link="l_upper_leg_inner_link"/>
  </joint>
  <link name="l_upper_leg_inner_link">
    <collision name="l_upper_leg_inner_collision">
      <origin rpy="-0.00000 -0.00000 -0.00000" xyz="-0.09287 0.00000 -0.01054"/>
      <geometry>
        <mesh filename="package://rmis/meshes/stl/l_upper_leg_link.stl" scale="0.10000 0.10000 0.10000"/>
      </geometry>
    </collision>
    <inertial>
      <inertia ixx="0.14374" ixy="-0.00539" ixz="-0.00179" iyy="0.09294" iyz="0.01231" izz="0.18306"/>
      <origin rpy="0.00000 0.00000 0.00000" xyz="-1.15800 -0.07651 0.08443"/>
      <mass value="0.05000"/>
    </inertial>
    <visual name="l_upper_leg_inner">
      <origin rpy="0.00000 0.00000 0.00000" xyz="-0.09287 0.00000 -0.01054"/>
      <geometry>
        <mesh filename="package://rmis/meshes/stl/l_upper_leg_link.stl" scale="0.10000 0.10000 0.10000"/>
      </geometry>
      <material name="grey"/>
    </visual>
  </link>
  <gazebo reference="l_upper_leg_inner_link">
    <material>Gazebo/Grey</material>
  </gazebo>

  <joint name="l_upper_leg_outer_link_joint" type="revolute">
    <origin xyz="0.14920 -0.09581 -0.02392" rpy="0.0 1.57080 0.0"/>
    <parent link="l_upper_leg_inner_link"/>
    <child link="l_upper_leg_outer_link"/>
    <axis xyz="0.0 0.0 1.0"/>
    <dynamics damping="0.50000" friction="0.1"/>
    <limit lower="-1.57" upper="1.57" effort="1.2" velocity="1.0"/>
  </joint>
  <link name="l_upper_leg_outer_link">
    <collision name="l_upper_leg_outer_collision">
      <origin rpy="-0.00000 -1.57080 0.00000" xyz="0.20410 0.00161 -0.21135"/>
      <geometry>
        <mesh filename="package://rmis/meshes/stl/l_upper_leg_joint.stl" scale="0.10000 0.10000 0.10000"/>
      </geometry>
    </collision>
    <inertial>
      <inertia ixx="0.28216" ixy="0.00029" ixz="0.00019" iyy="0.09091" iyz="-0.03166" izz="0.22118"/>
      <origin rpy="0.00000 0.00000 0.00000" xyz="1.61449 0.01137 -2.80674"/>
      <mass value="0.05000"/>
    </inertial>
    <visual name="l_upper_leg_outer">
      <origin rpy="-1.81578 -1.57080 1.81578" xyz="0.20410 0.00161 -0.21135"/>
      <geometry>
        <mesh filename="package://rmis/meshes/stl/l_upper_leg_joint.stl" scale="0.10000 0.10000 0.10000"/>
      </geometry>
      <material name="grey"/>
    </visual>
  </link>
  <gazebo reference="l_upper_leg_outer_link">
    <material>Gazebo/Grey</material>
  </gazebo>

  <joint name="l_lower_leg_inner_link_joint" type="fixed">
    <origin xyz="0.48106 -0.00032 -0.25524" rpy="-1.57080 -1.57080 1.57080"/>
    <parent link="l_upper_leg_outer_link"/>
    <child link="l_lower_leg_inner_link"/>
  </joint>
  <link name="l_lower_leg_inner_link">
    <collision name="l_lower_leg_inner_collision">
      <origin rpy="0.00000 -0.00000 0.00000" xyz="0.00000 -0.00000 -0.05855"/>
      <geometry>
        <mesh filename="package://rmis/meshes/stl/l_lower_leg_link.stl" scale="0.10000 0.10000 0.10000"/>
      </geometry>
    </collision>
    <inertial>
      <inertia ixx="0.36405" ixy="-0.00120" ixz="-0.00013" iyy="0.09410" iyz="-0.04544" izz="0.29049"/>
      <origin rpy="0.00000 0.00000 0.00000" xyz="-0.06622 -0.00438 -0.63853"/>
      <mass value="0.05000"/>
    </inertial>
    <visual name="l_lower_leg_inner">
      <origin rpy="-0.00000 0.00000 0.00000" xyz="0.00000 0.00000 -0.05855"/>
      <geometry>
        <mesh filename="package://rmis/meshes/stl/l_lower_leg_link.stl" scale="0.10000 0.10000 0.10000"/>
      </geometry>
      <material name="grey"/>
    </visual>
  </link>
  <gazebo reference="l_lower_leg_inner_link">
    <material>Gazebo/Grey</material>
  </gazebo>

  <joint name="l_lower_leg_outer_link_joint" type="revolute">
    <origin xyz="0.25524 0.00032 -0.18870" rpy="1.57080 1.57080 1.57080"/>
    <parent link="l_lower_leg_inner_link"/>
    <child link="l_lower_leg_outer_link"/>
    <axis xyz="0.0 0.0 1.0"/>
    <dynamics damping="0.50000" friction="0.1"/>
    <limit lower="-1.57" upper="1.57" effort="1.2" velocity="1.0"/>
  </joint>
  <link name="l_lower_leg_outer_link">
    <collision name="l_lower_leg_outer_collision">
      <origin rpy="1.57080 -1.57080 -1.57080" xyz="0.18053 0.00135 -0.25027"/>
      <geometry>
        <mesh filename="package://rmis/meshes/stl/l_lower_leg_joint.stl" scale="0.10000 0.10000 0.10000"/>
      </geometry>
    </collision>
    <inertial>
      <inertia ixx="0.23547" ixy="0.00000" ixz="0.00000" iyy="0.07973" iyz="0.00003" izz="0.18690"/>
      <origin rpy="0.00000 0.00000 0.00000" xyz="1.80531 0.01345 -2.50267"/>
      <mass value="0.05000"/>
    </inertial>
    <visual name="l_lower_leg_outer">
      <origin rpy="-1.57080 -1.57080 1.57080" xyz="0.18053 0.00135 -0.25027"/>
      <geometry>
        <mesh filename="package://rmis/meshes/stl/l_lower_leg_joint.stl" scale="0.10000 0.10000 0.10000"/>
      </geometry>
      <material name="grey"/>
    </visual>
  </link>
  <gazebo reference="l_lower_leg_outer_link">
    <material>Gazebo/Grey</material>
  </gazebo>

  <joint name="l_upper_ankle_link_joint" type="fixed">
    <origin xyz="0.49218 -0.00032 -0.25524" rpy="1.57079 -1.57080 -1.57080"/>
    <parent link="l_lower_leg_outer_link"/>
    <child link="l_upper_ankle_link"/>
  </joint>
  <link name="l_upper_ankle_link">
    <collision name="l_upper_ankle_collision">
      <origin rpy="-0.00000 -0.00000 -0.00000" xyz="0.00000 -0.00000 -0.04767"/>
      <geometry>
        <mesh filename="package://rmis/meshes/stl/l_ankle_link.stl" scale="0.10000 0.10000 0.10000"/>
      </geometry>
    </collision>
    <inertial>
      <inertia ixx="0.36405" ixy="-0.00120" ixz="-0.00013" iyy="0.09410" iyz="-0.04544" izz="0.29049"/>
      <origin rpy="0.00000 0.00000 0.00000" xyz="-0.06622 -0.00438 -0.52971"/>
      <mass value="0.05000"/>
    </inertial>
    <visual name="l_upper_ankle">
      <origin rpy="-0.00000 0.00000 -0.00000" xyz="0.00000 -0.00000 -0.04767"/>
      <geometry>
        <mesh filename="package://rmis/meshes/stl/l_ankle_link.stl" scale="0.10000 0.10000 0.10000"/>
      </geometry>
      <material name="grey"/>
    </visual>
  </link>
  <gazebo reference="l_upper_ankle_link">
    <material>Gazebo/Grey</material>
  </gazebo>

  <joint name="l_lower_ankle_link_joint" type="revolute">
    <origin xyz="0.25524 0.00032 -0.17729" rpy="0.0 1.57080 0.0"/>
    <parent link="l_upper_ankle_link"/>
    <child link="l_lower_ankle_link"/>
    <axis xyz="0.0 0.0 1.0"/>
    <dynamics damping="0.50000" friction="0.1"/>
    <limit lower="-0.3" upper="0.65" effort="1.2" velocity="1.0"/>
  </joint>
  <link name="l_lower_ankle_link">
    <collision name="l_lower_ankle_collision">
      <origin rpy="-0.00000 -1.57080 0.00000" xyz="0.18108 0.00135 -0.25027"/>
      <geometry>
        <mesh filename="package://rmis/meshes/stl/l_ankle_joint.stl" scale="0.10000 0.10000 0.10000"/>
      </geometry>
    </collision>
    <inertial>
      <inertia ixx="0.23547" ixy="0.00000" ixz="0.00000" iyy="0.07973" iyz="-0.00003" izz="0.18690"/>
      <origin rpy="0.00000 0.00000 0.00000" xyz="1.81079 0.01345 -2.50269"/>
      <mass value="0.05000"/>
    </inertial>
    <visual name="l_lower_ankle">
      <origin rpy="-1.32582 -1.57080 1.32582" xyz="0.18108 0.00135 -0.25027"/>
      <geometry>
        <mesh filename="package://rmis/meshes/stl/l_ankle_joint.stl" scale="0.10000 0.10000 0.10000"/>
      </geometry>
      <material name="grey"/>
    </visual>
  </link>
  <gazebo reference="l_lower_ankle_link">
    <material>Gazebo/Grey</material>
  </gazebo>

  <joint name="l_feet_link_joint" type="fixed">
    <origin xyz="0.29534 0.15614 -0.36302" rpy="-1.57080 -1.57080 1.57080"/>
    <parent link="l_lower_ankle_link"/>
    <child link="l_feet_link"/>
  </joint>
  <link name="l_feet_link">
    <collision name="l_feet_collision">
      <origin rpy="-0.00000 0.00000 -0.00000" xyz="0.05376 -0.00000 0.11108"/>
      <geometry>
        <mesh filename="package://rmis/meshes/stl/l_feet_link.stl" scale="0.10000 0.10000 0.10000"/>
      </geometry>
    </collision>
    <inertial>
      <inertia ixx="0.37179" ixy="-0.00718" ixz="-0.00237" iyy="0.56463" iyz="0.00152" izz="0.80037"/>
      <origin rpy="0.00000 0.00000 0.00000" xyz="0.53756 -0.00000 1.09638"/>
      <mass value="0.05000"/>
    </inertial>
    <visual name="l_feet">
      <origin rpy="-0.00000 0.00000 -0.00000" xyz="0.05376 -0.00000 0.11108"/>
      <geometry>
        <mesh filename="package://rmis/meshes/stl/l_feet_link.stl" scale="0.10000 0.10000 0.10000"/>
      </geometry>
      <material name="grey"/>
    </visual>
  </link>
  <gazebo reference="l_feet_link">
    <material>Gazebo/Grey</material>
  </gazebo>
  
  <gazebo>
  <plugin name="gazebo_ros2_control" filename="libgazebo_ros2_control.so">
    <robot_namespace>/rmis</robot_namespace>
    <control_plugins>
      <plugin name="joint_state_broadcaster" type="joint_state_broadcaster/JointStateBroadcaster"/>
    </control_plugins>
  </plugin>
</gazebo>
 
</robot>
