<?xml version="1.0"?>
<robot name="rmis" version="1.0">

  <!-- Dummy Link for KDL Parser -->
  <link name="world"/>

  <!-- Fixed Joint to Connect World to Base Link -->
  <joint name="world_to_base_joint" type="fixed">
    <parent link="world"/>
    <child link="base_link"/>
    <origin xyz="0.0 0.0 0.0" rpy="0.0 0.0 0.0"/>
  </joint>

  <!-- Base Link -->
  <link name="base_link">
    <inertial>
      <origin xyz="-0.00284 -0.01176 0.03521" rpy="0.0 0.0 0.0"/>
      <mass value="0.05000"/>
      <inertia ixx="3.80664" ixy="0.00010" ixz="-0.11562" iyy="2.86595" iyz="0.00147" izz="1.72824"/>
    </inertial>
    <visual name="base">
      <origin xyz="-0.15389 0.0 -0.00001" rpy="0.0 0.0 0.0"/>
      <geometry>
        <mesh filename="package://rmis/meshes/stl/base.stl" scale="0.1 0.1 0.1"/>
      </geometry>
      <material name="grey">
        <color rgba="0.5 0.5 0.5 1.0"/>
      </material>
    </visual>
    <collision name="base_collision">
      <origin xyz="-0.15389 0.0 -0.00001" rpy="0.0 0.0 0.0"/>
      <geometry>
        <mesh filename="package://rmis/meshes/stl/base.stl" scale="0.1 0.1 0.1"/>
      </geometry>
    </collision>
  </link>
  <gazebo reference="base_link">
    <material>Gazebo/Grey</material>
  </gazebo>

  <!-- Sensors Section -->
  <!-- Lidar -->
  <joint name="lidar_link_joint" type="fixed">
    <origin xyz="0.15210 0.54325 0.16884" rpy="0.0 0.0 0.0"/>
    <parent link="base_link"/>
    <child link="lidar_link"/>
  </joint>
  <link name="lidar_link">
    <inertial>
      <origin xyz="-1.54987 0.01466 -0.04121" rpy="0.0 0.0 0.0"/>
      <mass value="0.05000"/>
      <inertia ixx="0.05768" ixy="0.00012" ixz="-0.00062" iyy="0.02857" iyz="0.00006" izz="0.05022"/>
    </inertial>
    <visual name="lidar">
      <origin xyz="-0.15388 0.0 -0.00000" rpy="0.0 0.0 0.0"/>
      <geometry>
        <mesh filename="package://rmis/meshes/stl/TF_Luna.stl" scale="0.1 0.1 0.1"/>
      </geometry>
      <material name="black">
        <color rgba="0.0 0.0 0.0 1.0"/>
      </material>
    </visual>
    <collision name="lidar_collision">
      <origin xyz="-0.15388 0.0 -0.00001" rpy="0.0 0.0 0.0"/>
      <geometry>
        <mesh filename="package://rmis/meshes/stl/TF_Luna.stl" scale="0.1 0.1 0.1"/>
      </geometry>
    </collision>
  </link>
  <gazebo reference="lidar_link">
    <material>Gazebo/Black</material>
    <sensor name="tf_luna" type="ray">
      <pose>0.0 0.0 0.0 0.0 0.0 0.0</pose>
      <visualize>true</visualize>
      <update_rate>10</update_rate>
      <ray>
        <scan>
          <horizontal>
            <samples>100</samples>
            <resolution>0.01047</resolution>
            <min_angle>-0.52360</min_angle>
            <max_angle>0.52360</max_angle>
          </horizontal>
        </scan>
        <range>
          <min>0.2</min>
          <max>8.0</max>
          <resolution>0.01</resolution>
        </range>
      </ray>
      <plugin name="lidar_plugin" filename="libgazebo_ros_ray_sensor.so">
        <ros>
          <namespace>/rmis</namespace>
          <remapping>~/out:=lidar_scan</remapping>
        </ros>
        <frame_name>lidar_link</frame_name>
      </plugin>
    </sensor>
  </gazebo>

  <!-- IMU -->
  <joint name="imu_link_joint" type="fixed">
    <origin xyz="0.21039 -0.34355 -1.01118" rpy="0.0 0.0 1.57080"/>
    <parent link="base_link"/>
    <child link="imu_link"/>
  </joint>
  <link name="imu_link">
    <inertial>
      <origin xyz="0.0 2.30103 0.0" rpy="0.0 0.0 0.0"/>
      <mass value="0.05000"/>
      <inertia ixx="0.03333" ixy="0.0" ixz="0.0" iyy="0.01817" iyz="0.0" izz="0.01817"/>
    </inertial>
    <visual name="imu">
      <origin xyz="0.0 0.23010 0.0" rpy="0.0 0.0 0.0"/>
      <geometry>
        <box size="0.06 0.2 0.2"/>
      </geometry>
      <material name="blue">
        <color rgba="0.0 0.0 1.0 1.0"/>
      </material>
    </visual>
    <collision name="imu_collision">
      <origin xyz="0.0 0.23010 0.0" rpy="0.0 0.0 0.0"/>
      <geometry>
        <box size="0.06 0.2 0.2"/>
      </geometry>
    </collision>
  </link>
  <gazebo reference="imu_link">
    <material>Gazebo/Blue</material>
  </gazebo>

  <!-- Upper Body Section -->
  <joint name="u_upper_body_link_joint" type="revolute">
    <origin xyz="-0.00039 -0.01857 0.85581" rpy="0.0 0.0 0.0"/>
    <parent link="base_link"/>
    <child link="u_upper_body_link"/>
    <axis xyz="0.0 0.0 1.0"/>
    <dynamics damping="0.50000" friction="0.1"/>
    <limit lower="-3.14" upper="3.14" effort="1.2" velocity="1.0"/>
  </joint>
  <link name="u_upper_body_link">
    <inertial>
      <origin xyz="0.0 0.0 0.0" rpy="0.0 0.0 0.0"/>
      <mass value="0.01"/>
      <inertia ixx="0.001" ixy="0.0" ixz="0.0" iyy="0.001" iyz="0.0" izz="0.001"/>
    </inertial>
    <visual name="u_upper_body">
      <origin xyz="0.0 0.0 0.0" rpy="0.0 0.0 0.0"/>
      <geometry>
        <box size="0.1 0.1 0.1"/>
      </geometry>
      <material name="grey"/>
    </visual>
    <collision name="u_upper_body_collision">
      <origin xyz="0.0 0.0 0.0" rpy="0.0 0.0 0.0"/>
      <geometry>
        <box size="0.1 0.1 0.1"/>
      </geometry>
    </collision>
  </link>
  <gazebo reference="u_upper_body_link">
    <material>Gazebo/Grey</material>
  </gazebo>

  <!-- Head and Neck Section -->
  <joint name="neck_link_joint" type="fixed">
    <origin xyz="0.29394 -0.10231 0.17455" rpy="0.0 0.0 0.0"/>
    <parent link="u_upper_body_link"/>
    <child link="neck_link"/>
  </joint>
  <link name="neck_link">
    <inertial>
      <origin xyz="-2.94095 0.0 -0.40906" rpy="0.0 0.0 0.0"/>
      <mass value="0.05000"/>
      <inertia ixx="0.10411" ixy="0.0" ixz="0.02435" iyy="0.11152" iyz="0.0" izz="0.04042"/>
    </inertial>
    <visual name="neck">
      <origin xyz="-0.29410 0.0 -0.04091" rpy="0.0 0.0 0.0"/>
      <geometry>
        <mesh filename="package://rmis/meshes/stl/neck_joint.stl" scale="0.1 0.1 0.1"/>
      </geometry>
      <material name="grey"/>
    </visual>
    <collision name="neck_collision">
      <origin xyz="-0.29410 0.0 -0.04091" rpy="0.0 0.0 0.0"/>
      <geometry>
        <mesh filename="package://rmis/meshes/stl/neck_joint.stl" scale="0.1 0.1 0.1"/>
      </geometry>
    </collision>
  </link>
  <gazebo reference="neck_link">
    <material>Gazebo/Grey</material>
  </gazebo>

  <joint name="head_inner_link_joint" type="revolute">
    <origin xyz="-0.53928 0.10308 0.14213" rpy="-1.57080 -1.57080 1.57080"/>
    <parent link="neck_link"/>
    <child link="head_inner_link"/>
    <axis xyz="0.0 0.0 1.0"/>
    <dynamics damping="0.50000" friction="0.1"/>
    <limit lower="-0.4" upper="0.4" effort="1.2" velocity="1.0"/>
  </joint>
  <link name="head_inner_link">
    <inertial>
      <origin xyz="0.86758 -0.32559 -2.66080" rpy="0.0 0.0 0.0"/>
      <mass value="0.05000"/>
      <inertia ixx="0.18266" ixy="0.01279" ixz="0.00147" iyy="0.09287" iyz="0.00504" izz="0.14329"/>
    </inertial>
    <visual name="head_inner">
      <origin xyz="0.10230 0.02942 -0.18450" rpy="1.57080 1.57080 1.57080"/>
      <geometry>
        <mesh filename="package://rmis/meshes/stl/head_link.stl" scale="0.1 0.1 0.1"/>
      </geometry>
      <material name="grey"/>
    </visual>
    <collision name="head_inner_collision">
      <origin xyz="0.10230 0.02942 -0.18450" rpy="1.57080 1.57080 1.57080"/>
      <geometry>
        <mesh filename="package://rmis/meshes/stl/head_link.stl" scale="0.1 0.1 0.1"/>
      </geometry>
    </collision>
  </link>
  <gazebo reference="head_inner_link">
    <material>Gazebo/Grey</material>
  </gazebo>

  <joint name="head_outer_link_joint" type="fixed">
    <origin xyz="0.24166 -0.01105 -0.24237" rpy="1.57080 1.57080 1.57080"/>
    <parent link="head_inner_link"/>
    <child link="head_outer_link"/>
  </joint>
  <link name="head_outer_link">
    <inertial>
      <origin xyz="0.0 0.0 0.0" rpy="0.0 0.0 0.0"/>
      <mass value="0.01"/>
      <inertia ixx="0.001" ixy="0.0" ixz="0.0" iyy="0.001" iyz="0.0" izz="0.001"/>
    </inertial>
    <visual name="head_outer">
      <origin xyz="0.0 0.0 0.0" rpy="0.0 0.0 0.0"/>
      <geometry>
        <mesh filename="package://rmis/meshes/stl/head_joint.stl" scale="0.1 0.1 0.1"/>
      </geometry>
      <material name="grey"/>
    </visual>
    <collision name="head_outer_collision">
      <origin xyz="0.0 0.0 0.0" rpy="0.0 0.0 0.0"/>
      <geometry>
        <mesh filename="package://rmis/meshes/stl/head_joint.stl" scale="0.1 0.1 0.1"/>
      </geometry>
    </collision>
  </link>
  <gazebo reference="head_outer_link">
    <material>Gazebo/Grey</material>
  </gazebo>

  <joint name="camera_link_joint" type="fixed">
    <origin xyz="-0.00027 0.51877 -0.01898" rpy="0.0 0.0 1.57080"/>
    <parent link="head_outer_link"/>
    <child link="camera_link"/>
  </joint>
  <link name="camera_link">
    <inertial>
      <origin xyz="-5.04919 -0.00283 0.18436" rpy="0.0 0.0 0.0"/>
      <mass value="0.05000"/>
      <inertia ixx="0.35611" ixy="0.08645" ixz="0.03018" iyy="1.36268" iyz="-0.00299" izz="1.33173"/>
    </inertial>
    <visual name="camera">
      <origin xyz="-0.51877 -0.00027 0.01898" rpy="0.0 0.0 -1.57080"/>
      <geometry>
        <mesh filename="package://rmis/meshes/stl/head_joint.stl" scale="0.1 0.1 0.1"/>
      </geometry>
      <material name="black"/>
    </visual>
    <collision name="camera_collision">
      <origin xyz="-0.51877 -0.00027 0.01898" rpy="0.0 0.0 -1.57080"/>
      <geometry>
        <mesh filename="package://rmis/meshes/stl/head_joint.stl" scale="0.1 0.1 0.1"/>
      </geometry>
    </collision>
  </link>
  <gazebo reference="camera_link">
    <material>Gazebo/Black</material>
    <sensor name="rasp_cam" type="camera">
      <pose>0.02942 0.0 0.0 -0.0 1.57080 0.0</pose>
      <camera>
        <horizontal_fov>1.57080</horizontal_fov>
        <image>
          <width>3280</width>
          <height>2464</height>
          <format>R8G8B8</format>
        </image>
        <clip>
          <near>0.01</near>
          <far>100.0</far>
        </clip>
      </camera>
      <update_rate>30</update_rate>
      <visualize>true</visualize>
      <plugin name="camera_plugin" filename="libgazebo_ros_camera.so">
        <ros>
          <namespace>/rmis</namespace>
          <remapping>~/out:=camera/image_raw</remapping>
        </ros>
        <frame_name>camera_link</frame_name>
      </plugin>
    </sensor>
  </gazebo>

  <!-- Lower Body Section -->
  <joint name="lower_body_link_joint" type="fixed">
    <origin xyz="-0.04942 -0.07242 -1.16532" rpy="0.0 0.0 0.0"/>
    <parent link="base_link"/>
    <child link="lower_body_link"/>
  </joint>
  <link name="lower_body_link">
    <inertial>
      <origin xyz="0.45951 -0.12902 0.92811" rpy="0.0 0.0 0.0"/>
      <mass value="0.05000"/>
      <inertia ixx="1.03498" ixy="-0.00427" ixz="-0.00418" iyy="0.30934" iyz="-0.00367" izz="1.06913"/>
    </inertial>
    <visual name="lower_body">
      <origin xyz="-0.07498 0.0 0.12347" rpy="0.0 0.0 0.0"/>
      <geometry>
        <mesh filename="package://rmis/meshes/stl/lower_body_link.stl" scale="0.1 0.1 0.1"/>
      </geometry>
      <material name="grey"/>
    </visual>
    <collision name="lower_body_collision">
      <origin xyz="-0.07498 0.0 0.12347" rpy="0.0 0.0 0.0"/>
      <geometry>
        <mesh filename="package://rmis/meshes/stl/lower_body_link.stl" scale="0.1 0.1 0.1"/>
      </geometry>
    </collision>
  </link>
  <gazebo reference="lower_body_link">
    <material>Gazebo/Grey</material>
  </gazebo>

  <!-- Left Upper Body -->
  <joint name="l_upper_body_link_joint" type="revolute">
    <origin xyz="-1.02542 -0.10845 0.50152" rpy="0.0 -1.57080 0.0"/>
    <parent link="base_link"/>
    <child link="l_upper_body_link"/>
    <axis xyz="0.0 0.0 1.0"/>
    <dynamics damping="0.50000" friction="0.1"/>
    <limit lower="-2.0" upper="2.0" effort="1.2" velocity="1.0"/>
  </joint>
  <link name="l_upper_body_link">
    <inertial>
      <origin xyz="0.0 0.0 0.0" rpy="0.0 0.0 0.0"/>
      <mass value="0.01"/>
      <inertia ixx="0.001" ixy="0.0" ixz="0.0" iyy="0.001" iyz="0.0" izz="0.001"/>
    </inertial>
    <visual name="l_upper_body">
      <origin xyz="0.0 0.0 0.0" rpy="0.0 0.0 0.0"/>
      <geometry>
        <box size="0.1 0.1 0.1"/>
      </geometry>
      <material name="grey"/>
    </visual>
    <collision name="l_upper_body_collision">
      <origin xyz="0.0 0.0 0.0" rpy="0.0 0.0 0.0"/>
      <geometry>
        <box size="0.1 0.1 0.1"/>
      </geometry>
    </collision>
  </link>
  <gazebo reference="l_upper_body_link">
    <material>Gazebo/Grey</material>
  </gazebo>

  <!-- Right Upper Body -->
  <joint name="r_upper_body_link_joint" type="revolute">
    <origin xyz="1.02542 -0.10845 0.50152" rpy="0.0 1.57080 0.0"/>
    <parent link="base_link"/>
    <child link="r_upper_body_link"/>
    <axis xyz="0.0 0.0 1.0"/>
    <dynamics damping="0.50000" friction="0.1"/>
    <limit lower="-2.0" upper="2.0" effort="1.2" velocity="1.0"/>
  </joint>
  <link name="r_upper_body_link">
    <inertial>
      <origin xyz="0.0 0.0 0.0" rpy="0.0 0.0 0.0"/>
      <mass value="0.01"/>
      <inertia ixx="0.001" ixy="0.0" ixz="0.0" iyy="0.001" iyz="0.0" izz="0.001"/>
    </inertial>
    <visual name="r_upper_body">
      <origin xyz="0.0 0.0 0.0" rpy="0.0 0.0 0.0"/>
      <geometry>
        <box size="0.1 0.1 0.1"/>
      </geometry>
      <material name="grey"/>
    </visual>
    <collision name="r_upper_body_collision">
      <origin xyz="0.0 0.0 0.0" rpy="0.0 0.0 0.0"/>
      <geometry>
        <box size="0.1 0.1 0.1"/>
      </geometry>
    </collision>
  </link>
  <gazebo reference="r_upper_body_link">
    <material>Gazebo/Grey</material>
  </gazebo>

  <!-- Left Lower Body -->
  <joint name="l_lower_body_link_joint" type="revolute">
    <origin xyz="-0.43474 -0.11124 -0.22114" rpy="3.14159 0.0 3.14159"/>
    <parent link="lower_body_link"/>
    <child link="l_lower_body_link"/>
    <axis xyz="0.0 0.0 1.0"/>
    <dynamics damping="0.50000" friction="0.1"/>
    <limit lower="-0.3" upper="0.3" effort="1.2" velocity="1.0"/>
  </joint>
  <link name="l_lower_body_link">
    <inertial>
      <origin xyz="0.0 0.0 0.0" rpy="0.0 0.0 0.0"/>
      <mass value="0.01"/>
      <inertia ixx="0.001" ixy="0.0" ixz="0.0" iyy="0.001" iyz="0.0" izz="0.001"/>
    </inertial>
    <visual name="l_lower_body">
      <origin xyz="0.0 0.0 0.0" rpy="0.0 0.0 0.0"/>
      <geometry>
        <box size="0.1 0.1 0.1"/>
      </geometry>
      <material name="grey"/>
    </visual>
    <collision name="l_lower_body_collision">
      <origin xyz="0.0 0.0 0.0" rpy="0.0 0.0 0.0"/>
      <geometry>
        <box size="0.1 0.1 0.1"/>
      </geometry>
    </collision>
  </link>
  <gazebo reference="l_lower_body_link">
    <material>Gazebo/Grey</material>
  </gazebo>

  <!-- Right Lower Body -->
  <joint name="r_lower_body_link_joint" type="revolute">
    <origin xyz="0.53339 -0.11124 -0.22114" rpy="3.14159 0.0 3.14159"/>
    <parent link="lower_body_link"/>
    <child link="r_lower_body_link"/>
    <axis xyz="0.0 0.0 1.0"/>
    <dynamics damping="0.50000" friction="0.1"/>
    <limit lower="-0.3" upper="0.3" effort="1.2" velocity="1.0"/>
  </joint>
  <link name="r_lower_body_link">
    <inertial>
      <origin xyz="0.0 0.0 0.0" rpy="0.0 0.0 0.0"/>
      <mass value="0.01"/>
      <inertia ixx="0.001" ixy="0.0" ixz="0.0" iyy="0.001" iyz="0.0" izz="0.001"/>
    </inertial>
    <visual name="r_lower_body">
      <origin xyz="0.0 0.0 0.0" rpy="0.0 0.0 0.0"/>
      <geometry>
        <box size="0.1 0.1 0.1"/>
      </geometry>
      <material name="grey"/>
    </visual>
    <collision name="r_lower_body_collision">
      <origin xyz="0.0 0.0 0.0" rpy="0.0 0.0 0.0"/>
      <geometry>
        <box size="0.1 0.1 0.1"/>
      </geometry>
    </collision>
  </link>
  <gazebo reference="r_lower_body_link">
    <material>Gazebo/Grey</material>
  </gazebo>

  <!-- Left Hip Section -->
  <joint name="l_upper_hip_link_joint" type="fixed">
    <origin xyz="-0.08125 0.19501 0.16258" rpy="-3.14159 0.0 3.14159"/>
    <parent link="l_lower_body_link"/>
    <child link="l_upper_hip_link"/>
  </joint>
  <link name="l_upper_hip_link">
    <inertial>
      <origin xyz="-0.89692 -0.81581 0.04150" rpy="0.0 0.0 0.0"/>
      <mass value="0.05000"/>
      <inertia ixx="0.09287" ixy="-0.00504" ixz="-0.01279" iyy="0.14329" iyz="0.00147" izz="0.18266"/>
    </inertial>
    <visual name="l_upper_hip">
      <origin xyz="-0.07415 0.0 -0.05783" rpy="0.0 0.0 0.0"/>
      <geometry>
        <mesh filename="package://rmis/meshes/stl/l_hip_link.stl" scale="0.1 0.1 0.1"/>
      </geometry>
      <material name="grey"/>
    </visual>
    <collision name="l_upper_hip_collision">
      <origin xyz="-0.07415 0.0 -0.05783" rpy="0.0 0.0 0.0"/>
      <geometry>
        <mesh filename="package://rmis/meshes/stl/l_hip_link.stl" scale="0.1 0.1 0.1"/>
      </geometry>
    </collision>
  </link>
  <gazebo reference="l_upper_hip_link">
    <material>Gazebo/Grey</material>
  </gazebo>

  <joint name="l_lower_hip_link_joint" type="revolute">
    <origin xyz="-0.17610 0.18793 -0.02809" rpy="-1.57080 0.0 0.0"/>
    <parent link="l_upper_hip_link"/>
    <child link="l_lower_hip_link"/>
    <axis xyz="0.0 0.0 1.0"/>
    <dynamics damping="0.50000" friction="0.1"/>
    <limit lower="0.0" upper="0.65" effort="1.2" velocity="1.0"/>
  </joint>
  <link name="l_lower_hip_link">
    <inertial>
      <origin xyz="0.01024 2.04998 -2.16272" rpy="0.0 0.0 0.0"/>
      <mass value="0.05000"/>
      <inertia ixx="0.09091" ixy="0.00004" ixz="0.03172" iyy="0.28233" iyz="-0.00003" izz="0.22135"/>
    </inertial>
    <visual name="l_lower_hip">
      <origin xyz="0.00102 0.20500 -0.21627" rpy="1.57080 0.0 0.0"/>
      <geometry>
        <mesh filename="package://rmis/meshes/stl/l_hip_joint.stl" scale="0.1 0.1 0.1"/>
      </geometry>
      <material name="grey"/>
    </visual>
    <collision name="l_lower_hip_collision">
      <origin xyz="0.00102 0.20500 -0.21627" rpy="1.57080 0.0 0.0"/>
      <geometry>
        <mesh filename="package://rmis/meshes/stl/l_hip_joint.stl" scale="0.1 0.1 0.1"/>
      </geometry>
    </collision>
  </link>
  <gazebo reference="l_lower_hip_link">
    <material>Gazebo/Grey</material>
  </gazebo>

  <!-- Right Hip Section -->
  <joint name="r_upper_hip_link_joint" type="fixed">
    <origin xyz="0.00270 0.13586 0.14958" rpy="3.14159 0.0 3.14159"/>
    <parent link="r_lower_body_link"/>
    <child link="r_upper_hip_link"/>
  </joint>
  <link name="r_upper_hip_link">
    <inertial>
      <origin xyz="0.0 0.0 -0.02804" rpy="0.0 0.0 0.0"/>
      <mass value="0.01"/>
      <inertia ixx="0.001" ixy="0.0" ixz="0.0" iyy="0.001" iyz="0.0" izz="0.001"/>
    </inertial>
    <visual name="r_upper_hip">
      <origin xyz="0.0 0.0 -0.02805" rpy="0.0 0.0 0.0"/>
      <geometry>
        <mesh filename="package://rmis/meshes/stl/r_hip_link.stl" scale="0.1 0.1 0.1"/>
      </geometry>
      <material name="grey"/>
    </visual>
    <collision name="r_upper_hip_collision">
      <origin xyz="0.0 0.0 -0.02804" rpy="0.0 0.0 0.0"/>
      <geometry>
        <mesh filename="package://rmis/meshes/stl/r_hip_link.stl" scale="0.1 0.1 0.1"/>
      </geometry>
    </collision>
  </link>
  <gazebo reference="r_upper_hip_link">
    <material>Gazebo/Grey</material>
  </gazebo>

  <joint name="r_lower_hip_link_joint" type="revolute">
    <origin xyz="0.09774 0.24708 -0.04110" rpy="-1.57080 0.0 0.0"/>
    <parent link="r_upper_hip_link"/>
    <child link="r_lower_hip_link"/>
    <axis xyz="0.0 0.0 1.0"/>
    <dynamics damping="0.50000" friction="0.1"/>
    <limit lower="0.0" upper="0.65" effort="1.2" velocity="1.0"/>
  </joint>
  <link name="r_lower_hip_link">
    <inertial>
      <origin xyz="-0.00490 1.62450 -2.85692" rpy="0.0 0.0 0.0"/>
      <mass value="0.05000"/>
      <inertia ixx="0.09070" ixy="-0.00001" ixz="0.03156" iyy="0.28217" iyz="0.0" izz="0.22140"/>
    </inertial>
    <visual name="r_lower_hip">
      <origin xyz="-0.00049 0.16245 -0.28569" rpy="1.57080 0.0 0.0"/>
      <geometry>
        <mesh filename="package://rmis/meshes/stl/r_hip_joint.stl" scale="0.1 0.1 0.1"/>
      </geometry>
      <material name="grey"/>
    </visual>
    <collision name="r_lower_hip_collision">
      <origin xyz="-0.00049 0.16245 -0.28569" rpy="1.57080 0.0 0.0"/>
      <geometry>
        <mesh filename="package://rmis/meshes/stl/r_hip_joint.stl" scale="0.1 0.1 0.1"/>
      </geometry>
    </collision>
  </link>
  <gazebo reference="r_lower_hip_link">
    <material>Gazebo/Grey</material>
  </gazebo>

  <!-- Left Leg Section -->
  <joint name="l_upper_leg_inner_link_joint" type="fixed">
    <origin xyz="0.23325 0.42698 -0.25846" rpy="1.57080 0.0 0.0"/>
    <parent link="l_lower_hip_link"/>
    <child link="l_upper_leg_inner_link"/>
  </joint>
  <link name="l_upper_leg_inner_link">
    <inertial>
      <origin xyz="-1.15800 -0.07651 0.08443" rpy="0.0 0.0 0.0"/>
      <mass value="0.05000"/>
      <inertia ixx="0.14374" ixy="-0.00539" ixz="-0.00179" iyy="0.09294" iyz="0.01231" izz="0.18306"/>
    </inertial>
    <visual name="l_upper_leg_inner">
      <origin xyz="-0.09287 0.0 -0.01054" rpy="0.0 0.0 0.0"/>
      <geometry>
        <mesh filename="package://rmis/meshes/stl/l_upper_leg_link.stl" scale="0.1 0.1 0.1"/>
      </geometry>
      <material name="grey"/>
    </visual>
    <collision name="l_upper_leg_inner_collision">
      <origin xyz="-0.09287 0.0 -0.01054" rpy="0.0 0.0 0.0"/>
      <geometry>
        <mesh filename="package://rmis/meshes/stl/l_upper_leg_link.stl" scale="0.1 0.1 0.1"/>
      </geometry>
    </collision>
  </link>
  <gazebo reference="l_upper_leg_inner_link">
    <material>Gazebo/Grey</material>
  </gazebo>

  <joint name="l_upper_leg_outer_link_joint" type="revolute">
    <origin xyz="0.14920 -0.09581 -0.02392" rpy="0.0 1.57080 0.0"/>
    <parent link="l_upper_leg_inner_link"/>
    <child link="l_upper_leg_outer_link"/>
    <axis xyz="0.0 0.0 1.0"/>
    <dynamics damping="0.50000" friction="0.1"/>
    <limit lower="-1.57" upper="1.57" effort="1.2" velocity="1.0"/>
  </joint>
  <link name="l_upper_leg_outer_link">
    <inertial>
      <origin xyz="1.61449 0.01137 -2.80674" rpy="0.0 0.0 0.0"/>
      <mass value="0.05000"/>
      <inertia ixx="0.28216" ixy="0.00029" ixz="0.00019" iyy="0.09091" iyz="-0.03166" izz="0.22118"/>
    </inertial>
    <visual name="l_upper_leg_outer">
      <origin xyz="0.20410 0.00161 -0.21135" rpy="-1.81578 -1.57080 1.81578"/>
      <geometry>
        <mesh filename="package://rmis/meshes/stl/l_upper_leg_joint.stl" scale="0.1 0.1 0.1"/>
      </geometry>
      <material name="grey"/>
    </visual>
    <collision name="l_upper_leg_outer_collision">
      <origin xyz="0.20410 0.00161 -0.21135" rpy="-1.81578 -1.57080 1.81578"/>
      <geometry>
        <mesh filename="package://rmis/meshes/stl/l_upper_leg_joint.stl" scale="0.1 0.1 0.1"/>
      </geometry>
    </collision>
  </link>
  <gazebo reference="l_upper_leg_outer_link">
    <material>Gazebo/Grey</material>
  </gazebo>

  <joint name="l_lower_leg_inner_link_joint" type="fixed">
    <origin xyz="0.48106 -0.00032 -0.25524" rpy="-1.57080 -1.57080 1.57080"/>
    <parent link="l_upper_leg_outer_link"/>
    <child link="l_lower_leg_inner_link"/>
  </joint>
  <link name="l_lower_leg_inner_link">
    <inertial>
      <origin xyz="-0.06622 -0.00438 -0.63853" rpy="0.0 0.0 0.0"/>
      <mass value="0.05000"/>
      <inertia ixx="0.36405" ixy="-0.00120" ixz="-0.00013" iyy="0.09410" iyz="-0.04544" izz="0.29049"/>
    </inertial>
    <visual name="l_lower_leg_inner">
      <origin xyz="0.0 0.0 -0.05855" rpy="0.0 0.0 0.0"/>
      <geometry>
        <mesh filename="package://rmis/meshes/stl/l_lower_leg_link.stl" scale="0.1 0.1 0.1"/>
      </geometry>
      <material name="grey"/>
    </visual>
    <collision name="l_lower_leg_inner_collision">
      <origin xyz="0.0 0.0 -0.05855" rpy="0.0 0.0 0.0"/>
      <geometry>
        <mesh filename="package://rmis/meshes/stl/l_lower_leg_link.stl" scale="0.1 0.1 0.1"/>
      </geometry>
    </collision>
  </link>
  <gazebo reference="l_lower_leg_inner_link">
    <material>Gazebo/Grey</material>
  </gazebo>

  <joint name="l_lower_leg_outer_link_joint" type="revolute">
    <origin xyz="0.25524 0.00032 -0.18870" rpy="1.57080 1.57080 1.57080"/>
    <parent link="l_lower_leg_inner_link"/>
    <child link="l_lower_leg_outer_link"/>
    <axis xyz="0.0 0.0 1.0"/>
    <dynamics damping="0.50000" friction="0.1"/>
    <limit lower="-1.57" upper="1.57" effort="1.2" velocity="1.0"/>
  </joint>
  <link name="l_lower_leg_outer_link">
    <inertial>
      <origin xyz="1.80531 0.01345 -2.50267" rpy="0.0 0.0 0.0"/>
      <mass value="0.05000"/>
      <inertia ixx="0.23547" ixy="0.0" ixz="0.0" iyy="0.07973" iyz="0.00003" izz="0.18690"/>
    </inertial>
    <visual name="l_lower_leg_outer">
      <origin xyz="0.18053 0.00135 -0.25027" rpy="-1.57080 -1.57080 1.57080"/>
      <geometry>
        <mesh filename="package://rmis/meshes/stl/l_lower_leg_joint.stl" scale="0.1 0.1 0.1"/>
      </geometry>
      <material name="grey"/>
    </visual>
    <collision name="l_lower_leg_outer_collision">
      <origin xyz="0.18053 0.00135 -0.25027" rpy="-1.57080 -1.57080 1.57080"/>
      <geometry>
        <mesh filename="package://rmis/meshes/stl/l_lower_leg_joint.stl" scale="0.1 0.1 0.1"/>
      </geometry>
    </collision>
  </link>
  <gazebo reference="l_lower_leg_outer_link">
    <material>Gazebo/Grey</material>
  </gazebo>

  <joint name="l_upper_ankle_link_joint" type="fixed">
    <origin xyz="0.49218 -0.00032 -0.25524" rpy="1.57079 -1.57080 -1.57080"/>
    <parent link="l_lower_leg_outer_link"/>
    <child link="l_upper_ankle_link"/>
  </joint>
  <link name="l_upper_ankle_link">
    <inertial>
      <origin xyz="-0.06622 -0.00438 -0.52971" rpy="0.0 0.0 0.0"/>
      <mass value="0.05000"/>
      <inertia ixx="0.36405" ixy="-0.00120" ixz="-0.00013" iyy="0.09410" iyz="-0.04544" izz="0.29049"/>
    </inertial>
    <visual name="l_upper_ankle">
      <origin xyz="0.0 0.0 -0.04767" rpy="0.0 0.0 0.0"/>
      <geometry>
        <mesh filename="package://rmis/meshes/stl/l_ankle_link.stl" scale="0.1 0.1 0.1"/>
      </geometry>
      <material name="grey"/>
    </visual>
    <collision name="l_upper_ankle_collision">
      <origin xyz="0.0 0.0 -0.04767" rpy="0.0 0.0 0.0"/>
      <geometry>
        <mesh filename="package://rmis/meshes/stl/l_ankle_link.stl" scale="0.1 0.1 0.1"/>
      </geometry>
    </collision>
  </link>
  <gazebo reference="l_upper_ankle_link">
    <material>Gazebo/Grey</material>
  </gazebo>

  <joint name="l_lower_ankle_link_joint" type="revolute">
    <origin xyz="0.25524 0.00032 -0.17729" rpy="0.0 1.57080 0.0"/>
    <parent link="l_upper_ankle_link"/>
    <child link="l_lower_ankle_link"/>
    <axis xyz="0.0 0.0 1.0"/>
    <dynamics damping="0.50000" friction="0.1"/>
    <limit lower="-0.3" upper="0.65" effort="1.2" velocity="1.0"/>
  </joint>
  <link name="l_lower_ankle_link">
    <inertial>
      <origin xyz="1.81079 0.01345 -2.50269" rpy="0.0 0.0 0.0"/>
      <mass value="0.05000"/>
      <inertia ixx="0.23547" ixy="0.0" ixz="0.0" iyy="0.07973" iyz="-0.00003" izz="0.18690"/>
    </inertial>
    <visual name="l_lower_ankle">
      <origin xyz="0.18108 0.00135 -0.25027" rpy="-1.32582 -1.57080 1.32582"/>
      <geometry>
        <mesh filename="package://rmis/meshes/stl/l_ankle_joint.stl" scale="0.1 0.1 0.1"/>
      </geometry>
      <material name="grey"/>
    </visual>
    <collision name="l_lower_ankle_collision">
      <origin xyz="0.18108 0.00135 -0.25027" rpy="-1.32582 -1.57080 1.32582"/>
      <geometry>
        <mesh filename="package://rmis/meshes/stl/l_ankle_joint.stl" scale="0.1 0.1 0.1"/>
      </geometry>
    </collision>
  </link>
  <gazebo reference="l_lower_ankle_link">
    <material>Gazebo/Grey</material>
  </gazebo>

  <joint name="l_feet_link_joint" type="fixed">
    <origin xyz="0.29534 0.15614 -0.36302" rpy="-1.57080 -1.57080 1.57080"/>
    <parent link="l_lower_ankle_link"/>
    <child link="l_feet_link"/>
  </joint>
  <link name="l_feet_link">
    <inertial>
      <origin xyz="0.53756 0.0 1.09638" rpy="0.0 0.0 0.0"/>
      <mass value="0.05000"/>
      <inertia ixx="0.37179" ixy="-0.00718" ixz="-0.00237" iyy="0.56463" iyz="0.00152" izz="0.80037"/>
    </inertial>
    <visual name="l_feet">
      <origin xyz="0.05376 0.0 0.11108" rpy="0.0 0.0 0.0"/>
      <geometry>
        <mesh filename="package://rmis/meshes/stl/l_feet_link.stl" scale="0.1 0.1 0.1"/>
      </geometry>
      <material name="grey"/>
    </visual>
    <collision name="l_feet_collision">
      <origin xyz="0.05376 0.0 0.11108" rpy="0.0 0.0 0.0"/>
      <geometry>
        <mesh filename="package://rmis/meshes/stl/l_feet_link.stl" scale="0.1 0.1 0.1"/>
      </geometry>
    </collision>
  </link>
  <gazebo reference="l_feet_link">
    <material>Gazebo/Grey</material>
  </gazebo>

  <!-- Right Leg Section -->
        <joint name="r_upper_leg_inner_link_joint" type="fixed">
      <origin xyz="-0.00314 -0.10590 -0.15035" rpy="1.57079 1.57080 1.57079"/>
      <parent link="r_lower_hip_link"/>
      <child link="r_upper_leg_inner_link"/>
    </joint>
    <link name="r_upper_leg_inner_link">
      <inertial>
        <origin xyz="0.21242 -0.01084 -0.01650" rpy="0.0 0.0 0.0"/>
        <mass value="0.05000"/>
        <inertia ixx="0.07973" ixy="0.00003" ixz="0.0" iyy="0.18690" iyz="0.0" izz="0.23547"/>
      </inertial>
      <visual name="r_upper_leg_inner">
        <origin xyz="0.02124 -0.00108 -0.00165" rpy="0.0 0.0 0.0"/>
        <geometry>
          <mesh filename="package://rmis/meshes/stl/r_upper_leg_link.stl" scale="0.1 0.1 0.1"/>
        </geometry>
        <material name="grey"/>
      </visual>
      <collision name="r_upper_leg_inner_collision">
        <origin xyz="0.02124 -0.00108 -0.00165" rpy="0.0 0.0 0.0"/>
        <geometry>
          <mesh filename="package://rmis/meshes/stl/r_upper_leg_link.stl" scale="0.1 0.1 0.1"/>
        </geometry>
      </collision>
    </link>
    <gazebo reference="r_upper_leg_inner_link">
      <material>Gazebo/Grey</material>
    </gazebo>
    
<joint name="r_upper_leg_outer_link_joint" type="revolute">
    <origin xyz="-0.15574 -0.10590 -0.00315" rpy="-1.57079 -1.57080 1.57079"/>
    <parent link="r_upper_leg_inner_link"/>
    <child link="r_upper_leg_outer_link"/>
    <axis xyz="0.0 0.0 1.0"/>
    <dynamics damping="0.50000" friction="0.1"/>
    <limit lower="-1.57" upper="1.57" effort="1.2" velocity="1.0"/>
  </joint>
  <link name="r_upper_leg_outer_link">
    <inertial>
      <origin xyz="-1.61459 0.05261 -2.83045" rpy="0.0 0.0 0.0"/>
      <mass value="0.05000"/>
      <inertia ixx="0.28227" ixy="0.00029" ixz="-0.00019" iyy="0.09090" iyz="0.03170" izz="0.22130"/>
    </inertial>
    <visual name="r_upper_leg_outer">
      <origin xyz="-0.20411 0.00479 -0.21364" rpy="1.57080 1.57080 1.57080"/>
      <geometry>
        <mesh filename="package://rmis/meshes/stl/r_upper_leg_joint.stl" scale="0.1 0.1 0.1"/>
      </geometry>
      <material name="grey"/>
    </visual>
    <collision name="r_upper_leg_outer_collision">
      <origin xyz="-0.20411 0.00479 -0.21364" rpy="1.57080 1.57080 1.57080"/>
      <geometry>
        <mesh filename="package://rmis/meshes/stl/r_upper_leg_joint.stl" scale="0.1 0.1 0.1"/>
      </geometry>
    </collision>
  </link>
  <gazebo reference="r_upper_leg_outer_link">
    <material>Gazebo/Grey</material>
  </gazebo>

  <joint name="r_lower_leg_inner_link_joint" type="fixed">
    <origin xyz="-0.50982 0.00553 -0.28932" rpy="-1.57079 1.57080 -1.57080"/>
    <parent link="r_upper_leg_outer_link"/>
    <child link="r_lower_leg_inner_link"/>
  </joint>
  <link name="r_lower_leg_inner_link">
    <inertial>
      <origin xyz="-0.25026 -0.01220 -0.35379" rpy="0.0 0.0 0.0"/>
      <mass value="0.05000"/>
      <inertia ixx="0.36405" ixy="-0.00120" ixz="0.00013" iyy="0.09410" iyz="0.04544" izz="0.29049"/>
    </inertial>
    <visual name="r_lower_leg_inner">
      <origin xyz="-0.03165 -0.00166 -0.03008" rpy="0.0 0.0 0.0"/>
      <geometry>
        <mesh filename="package://rmis/meshes/stl/r_lower_leg_link.stl" scale="0.1 0.1 0.1"/>
      </geometry>
      <material name="grey"/>
    </visual>
    <collision name="r_lower_leg_inner_collision">
      <origin xyz="-0.03165 -0.00166 -0.03008" rpy="0.0 0.0 0.0"/>
      <geometry>
        <mesh filename="package://rmis/meshes/stl/r_lower_leg_link.stl" scale="0.1 0.1 0.1"/>
      </geometry>
    </collision>
  </link>
  <gazebo reference="r_lower_leg_inner_link">
    <material>Gazebo/Grey</material>
  </gazebo>

  <joint name="r_lower_leg_outer_link_joint" type="revolute">
    <origin xyz="-0.28933 -0.00553 -0.15922" rpy="0.0 -1.57080 0.0"/>
    <parent link="r_lower_leg_inner_link"/>
    <child link="r_lower_leg_outer_link"/>
    <axis xyz="0.0 0.0 1.0"/>
    <dynamics damping="0.50000" friction="0.1"/>
    <limit lower="-1.57" upper="1.57" effort="1.2" velocity="1.0"/>
  </joint>
  <link name="r_lower_leg_outer_link">
    <inertial>
      <origin xyz="-1.81259 0.05530 -2.52645" rpy="0.0 0.0 0.0"/>
      <mass value="0.05000"/>
      <inertia ixx="0.23547" ixy="0.0" ixz="0.0" iyy="0.07973" iyz="-0.00003" izz="0.18690"/>
    </inertial>
    <visual name="r_lower_leg_outer">
      <origin xyz="-0.18126 0.00553 -0.25265" rpy="1.57080 1.57080 1.57080"/>
      <geometry>
        <mesh filename="package://rmis/meshes/stl/r_lower_leg_joint.stl" scale="0.1 0.1 0.1"/>
      </geometry>
      <material name="grey"/>
    </visual>
    <collision name="r_lower_leg_outer_collision">
      <origin xyz="-0.18126 0.00553 -0.25265" rpy="1.57080 1.57080 1.57080"/>
      <geometry>
        <mesh filename="package://rmis/meshes/stl/r_lower_leg_joint.stl" scale="0.1 0.1 0.1"/>
      </geometry>
    </collision>
  </link>
  <gazebo reference="r_lower_leg_outer_link">
    <material>Gazebo/Grey</material>
  </gazebo>

  <joint name="r_upper_ankle_link_joint" type="fixed">
    <origin xyz="-0.58812 0.00553 -0.28932" rpy="1.57080 1.57080 1.57080"/>
    <parent link="r_lower_leg_outer_link"/>
    <child link="r_upper_ankle_link"/>
  </joint>
  <link name="r_upper_ankle_link">
    <inertial>
      <origin xyz="-0.25087 -0.01220 0.42255" rpy="0.0 0.0 0.0"/>
      <mass value="0.05000"/>
      <inertia ixx="0.36405" ixy="-0.00120" ixz="0.00013" iyy="0.09410" iyz="0.04544" izz="0.29049"/>
    </inertial>
    <visual name="r_upper_ankle">
      <origin xyz="-0.03171 -0.00166 0.04755" rpy="0.0 0.0 0.0"/>
      <geometry>
        <mesh filename="package://rmis/meshes/stl/r_ankle_link.stl" scale="0.1 0.1 0.1"/>
      </geometry>
      <material name="grey"/>
    </visual>
    <collision name="r_upper_ankle_collision">
      <origin xyz="-0.03171 -0.00166 0.04755" rpy="0.0 0.0 0.0"/>
      <geometry>
        <mesh filename="package://rmis/meshes/stl/r_ankle_link.stl" scale="0.1 0.1 0.1"/>
      </geometry>
    </collision>
  </link>
  <gazebo reference="r_upper_ankle_link">
    <material>Gazebo/Grey</material>
  </gazebo>
  
  <joint name="r_lower_ankle_link_joint" type="revolute">
    <origin xyz="-0.28932 -0.00553 -0.08191" rpy="0.0 -1.57080 0.0"/>
    <parent link="r_upper_ankle_link"/>
    <child link="r_lower_ankle_link"/>
    <axis xyz="0.0 0.0 1.0"/>
    <dynamics damping="0.50000" friction="0.1"/>
    <limit lower="-0.65" upper="0.3" effort="1.2" velocity="1.0"/>
  </joint>
  <link name="r_lower_ankle_link">
    <inertial>
      <origin xyz="-1.81224 0.05529 -2.52645" rpy="0.0 0.0 0.0"/>
      <mass value="0.05000"/>
      <inertia ixx="0.23547" ixy="0.0" ixz="0.0" iyy="0.07973" iyz="-0.00003" izz="0.18690"/>
    </inertial>
    <visual name="r_lower_ankle">
      <origin xyz="-0.18123 0.00553 -0.25265" rpy="1.44644 1.57080 1.44644"/>
      <geometry>
        <mesh filename="package://rmis/meshes/stl/r_ankle_joint.stl" scale="0.1 0.1 0.1"/>
      </geometry>
      <material name="grey"/>
    </visual>
    <collision name="r_lower_ankle_collision">
      <origin xyz="-0.18123 0.00553 -0.25265" rpy="1.44644 1.57080 1.44644"/>
      <geometry>
        <mesh filename="package://rmis/meshes/stl/r_lower_ankle_link.stl" scale="0.1 0.1 0.1"/>
      </geometry>
    </collision>
  </link>
  <gazebo reference="r_lower_ankle_link">
    <material>Gazebo/Grey</material>
  </gazebo>
  
    <!-- Left Arm Section -->
    <joint name="l_upper_shoulder_link_joint" type="fixed">
      <origin xyz="0.00314 0.00023 0.15035" rpy="1.64773 1.57080 1.64773"/>
      <parent link="l_upper_body_link"/>
      <child link="l_upper_shoulder_link"/>
    </joint>
    <link name="l_upper_shoulder_link">
      <inertial>
        <origin xyz="0.21242 -0.01084 -0.01650" rpy="0.0 0.0 0.0"/>
        <mass value="0.05000"/>
        <inertia ixx="0.07973" ixy="0.00003" ixz="0.0" iyy="0.18690" iyz="0.0" izz="0.23547"/>
      </inertial>
      <visual name="l_upper_shoulder">
        <origin xyz="0.02124 -0.00108 -0.00165" rpy="0.0 0.0 0.0"/>
        <geometry>
          <mesh filename="package://rmis/meshes/stl/l_shoulder_link.stl" scale="0.1 0.1 0.1"/>
        </geometry>
        <material name="grey"/>
      </visual>
      <collision name="l_upper_shoulder_collision">
        <origin xyz="0.02124 -0.00108 -0.00165" rpy="0.0 0.0 0.0"/>
        <geometry>
          <mesh filename="package://rmis/meshes/stl/l_shoulder_link.stl" scale="0.1 0.1 0.1"/>
        </geometry>
      </collision>
    </link>
    <gazebo reference="l_upper_shoulder_link">
      <material>Gazebo/Grey</material>
    </gazebo>

    <joint name="l_lower_shoulder_upper_link_joint" type="revolute">
      <origin xyz="-0.15786 0.25015 0.0" rpy="-1.57080 0.0 0.0"/>
      <parent link="l_upper_shoulder_link"/>
      <child link="l_lower_shoulder_upper_link"/>
      <axis xyz="0.0 0.0 1.0"/>
      <dynamics damping="0.50000" friction="0.1"/>
      <limit lower="0.0" upper="1.57" effort="1.2" velocity="1.0"/>
    </joint>
    <link name="l_lower_shoulder_upper_link">
      <inertial>
        <origin xyz="0.0 0.0 0.0" rpy="0.0 0.0 0.0"/>
        <mass value="0.01"/>
        <inertia ixx="0.001" ixy="0.0" ixz="0.0" iyy="0.001" iyz="0.0" izz="0.001"/>
      </inertial>
      <visual name="l_lower_shoulder_upper">
        <origin xyz="0.0 0.0 0.0" rpy="0.0 0.0 0.0"/>
        <geometry>
          <box size="0.1 0.1 0.1"/>
        </geometry>
        <material name="grey"/>
      </visual>
      <collision name="l_lower_shoulder_upper_collision">
        <origin xyz="0.0 0.0 0.0" rpy="0.0 0.0 0.0"/>
        <geometry>
          <box size="0.1 0.1 0.1"/>
        </geometry>
      </collision>
    </link>
    <gazebo reference="l_lower_shoulder_upper_link">
      <material>Gazebo/Grey</material>
    </gazebo>

    <joint name="l_lower_shoulder_link_joint" type="fixed">
      <origin xyz="0.01024 0.62216 -0.27345" rpy="1.57080 0.0 0.0"/>
      <parent link="l_lower_shoulder_upper_link"/>
      <child link="l_lower_shoulder_link"/>
    </joint>
    <link name="l_lower_shoulder_link">
      <inertial>
        <origin xyz="0.0 0.0 0.0" rpy="0.0 0.0 0.0"/>
        <mass value="0.01"/>
        <inertia ixx="0.001" ixy="0.0" ixz="0.0" iyy="0.001" iyz="0.0" izz="0.001"/>
      </inertial>
      <visual name="l_lower_shoulder">
        <origin xyz="0.0 0.0 0.0" rpy="0.0 0.0 0.0"/>
        <geometry>
          <mesh filename="package://rmis/meshes/stl/l_shoulder_joint.stl" scale="0.1 0.1 0.1"/>
        </geometry>
        <material name="grey"/>
      </visual>
      <collision name="l_lower_shoulder_collision">
        <origin xyz="0.0 0.0 0.0" rpy="0.0 0.0 0.0"/>
        <geometry>
          <mesh filename="package://rmis/meshes/stl/l_shoulder_joint.stl" scale="0.1 0.1 0.1"/>
        </geometry>
      </collision>
    </link>
    <gazebo reference="l_lower_shoulder_link">
      <material>Gazebo/Grey</material>
    </gazebo>

    <joint name="l_upper_arm_upper_link_joint" type="revolute">
      <origin xyz="0.0 0.0 0.0" rpy="0.0 0.0 0.0"/>
      <parent link="l_lower_shoulder_link"/>
      <child link="l_upper_arm_upper_link"/>
      <axis xyz="0.0 0.0 1.0"/>
      <dynamics damping="0.50000" friction="0.1"/>
      <limit lower="-1.57" upper="1.57" effort="1.2" velocity="1.0"/>
    </joint>
    <link name="l_upper_arm_upper_link">
      <inertial>
        <origin xyz="0.0 0.0 0.0" rpy="0.0 0.0 0.0"/>
        <mass value="0.01"/>
        <inertia ixx="0.001" ixy="0.0" ixz="0.0" iyy="0.001" iyz="0.0" izz="0.001"/>
      </inertial>
      <visual name="l_upper_arm_upper">
        <origin xyz="0.0 0.0 0.0" rpy="0.0 0.0 0.0"/>
        <geometry>
          <mesh filename="package://rmis/meshes/stl/l_upper_arm_link.stl" scale="0.1 0.1 0.1"/>
        </geometry>
        <material name="grey"/>
      </visual>
      <collision name="l_upper_arm_upper_collision">
        <origin xyz="0.0 0.0 0.0" rpy="0.0 0.0 0.0"/>
        <geometry>
          <mesh filename="package://rmis/meshes/stl/l_upper_arm_link.stl" scale="0.1 0.1 0.1"/>
        </geometry>
      </collision>
    </link>
    <gazebo reference="l_upper_arm_upper_link">
      <material>Gazebo/Grey</material>
    </gazebo>

    <joint name="l_upper_arm_lower_link_joint" type="revolute">
      <origin xyz="0.0 0.3 0.0" rpy="0.0 0.0 0.0"/>
      <parent link="l_upper_arm_upper_link"/>
      <child link="l_upper_arm_lower_link"/>
      <axis xyz="0.0 0.0 1.0"/>
      <dynamics damping="0.50000" friction="0.1"/>
      <limit lower="-1.57" upper="1.57" effort="1.2" velocity="1.0"/>
    </joint>
    <link name="l_upper_arm_lower_link">
      <inertial>
        <origin xyz="0.0 0.0 0.0" rpy="0.0 0.0 0.0"/>
        <mass value="0.01"/>
        <inertia ixx="0.001" ixy="0.0" ixz="0.0" iyy="0.001" iyz="0.0" izz="0.001"/>
      </inertial>
      <visual name="l_upper_arm_lower">
        <origin xyz="0.0 0.0 0.0" rpy="0.0 0.0 0.0"/>
        <geometry>
          <mesh filename="package://rmis/meshes/stl/l_upper_arm_joint.stl" scale="0.1 0.1 0.1"/>
        </geometry>
        <material name="grey"/>
      </visual>
      <collision name="l_upper_arm_lower_collision">
        <origin xyz="0.0 0.0 0.0" rpy="0.0 0.0 0.0"/>
        <geometry>
          <mesh filename="package://rmis/meshes/stl/l_upper_arm_joint.stl" scale="0.1 0.1 0.1"/>
        </geometry>
      </collision>
    </link>
    <gazebo reference="l_upper_arm_lower_link">
      <material>Gazebo/Grey</material>
    </gazebo>

    <joint name="l_lower_arm_upper_link_joint" type="revolute">
      <origin xyz="0.0 0.3 0.0" rpy="0.0 0.0 0.0"/>
      <parent link="l_upper_arm_lower_link"/>
      <child link="l_lower_arm_upper_link"/>
      <axis xyz="0.0 0.0 1.0"/>
      <dynamics damping="0.50000" friction="0.1"/>
      <limit lower="-1.57" upper="1.57" effort="1.2" velocity="1.0"/>
    </joint>
    <link name="l_lower_arm_upper_link">
      <inertial>
        <origin xyz="0.0 0.0 0.0" rpy="0.0 0.0 0.0"/>
        <mass value="0.01"/>
        <inertia ixx="0.001" ixy="0.0" ixz="0.0" iyy="0.001" iyz="0.0" izz="0.001"/>
      </inertial>
      <visual name="l_lower_arm_upper">
        <origin xyz="0.0 0.0 0.0" rpy="0.0 0.0 0.0"/>
        <geometry>
          <mesh filename="package://rmis/meshes/stl/l_lower_arm_link.stl" scale="0.1 0.1 0.1"/>
        </geometry>
        <material name="grey"/>
      </visual>
      <collision name="l_lower_arm_upper_collision">
        <origin xyz="0.0 0.0 0.0" rpy="0.0 0.0 0.0"/>
        <geometry>
          <mesh filename="package://rmis/meshes/stl/l_lower_arm_link.stl" scale="0.1 0.1 0.1"/>
        </geometry>
      </collision>
    </link>
    <gazebo reference="l_lower_arm_upper_link">
      <material>Gazebo/Grey</material>
    </gazebo>

    <joint name="l_lower_arm_lower_link_joint" type="revolute">
      <origin xyz="0.0 0.3 0.0" rpy="0.0 0.0 0.0"/>
      <parent link="l_lower_arm_upper_link"/>
      <child link="l_lower_arm_lower_link"/>
      <axis xyz="0.0 0.0 1.0"/>
      <dynamics damping="0.50000" friction="0.1"/>
      <limit lower="-1.57" upper="1.57" effort="1.2" velocity="1.0"/>
    </joint>
    <link name="l_lower_arm_lower_link">
      <inertial>
        <origin xyz="0.0 0.0 0.0" rpy="0.0 0.0 0.0"/>
        <mass value="0.01"/>
        <inertia ixx="0.001" ixy="0.0" ixz="0.0" iyy="0.001" iyz="0.0" izz="0.001"/>
      </inertial>
      <visual name="l_lower_arm_lower">
        <origin xyz="0.0 0.0 0.0" rpy="0.0 0.0 0.0"/>
        <geometry>
          <mesh filename="package://rmis/meshes/stl/l_lower_arm_joint.stl" scale="0.1 0.1 0.1"/>
        </geometry>
        <material name="grey"/>
      </visual>
      <collision name="l_lower_arm_lower_collision">
        <origin xyz="0.0 0.0 0.0" rpy="0.0 0.0 0.0"/>
        <geometry>
          <mesh filename="package://rmis/meshes/stl/l_lower_arm_joint.stl" scale="0.1 0.1 0.1"/>
        </geometry>
      </collision>
    </link>
    <gazebo reference="l_lower_arm_lower_link">
      <material>Gazebo/Grey</material>
    </gazebo>

    <joint name="l_hand_link_joint" type="fixed">
      <origin xyz="0.0 0.2 0.0" rpy="0.0 0.0 0.0"/>
      <parent link="l_lower_arm_lower_link"/>
      <child link="l_hand_link"/>
    </joint>
    <link name="l_hand_link">
      <inertial>
        <origin xyz="0.0 0.0 0.0" rpy="0.0 0.0 0.0"/>
        <mass value="0.01"/>
        <inertia ixx="0.001" ixy="0.0" ixz="0.0" iyy="0.001" iyz="0.0" izz="0.001"/>
      </inertial>
      <visual name="l_hand">
        <origin xyz="0.0 0.0 0.0" rpy="0.0 0.0 0.0"/>
        <geometry>
          <mesh filename="package://rmis/meshes/stl/l_hand_link.stl" scale="0.1 0.1 0.1"/>
        </geometry>
        <material name="grey"/>
      </visual>
      <collision name="l_hand_collision">
        <origin xyz="0.0 0.0 0.0" rpy="0.0 0.0 0.0"/>
        <geometry>
          <mesh filename="package://rmis/meshes/stl/l_hand_link.stl" scale="0.1 0.1 0.1"/>
        </geometry>
      </collision>
    </link>
    <gazebo reference="l_hand_link">
      <material>Gazebo/Grey</material>
    </gazebo>
  
  <!-- Right Arm Section -->
    <joint name="r_upper_shoulder_link_joint" type="fixed">
      <origin xyz="0.00314 -0.00023 0.15035" rpy="-1.64773 1.57080 -1.64773"/> <!-- Mirrored for right side -->
      <parent link="r_upper_body_link"/>
      <child link="r_upper_shoulder_link"/>
    </joint>
    <link name="r_upper_shoulder_link">
      <inertial>
        <origin xyz="0.21242 0.01084 -0.01650" rpy="0.0 0.0 0.0"/>
        <mass value="0.05000"/>
        <inertia ixx="0.07973" ixy="0.00003" ixz="0.0" iyy="0.18690" iyz="0.0" izz="0.23547"/>
      </inertial>
      <visual name="r_upper_shoulder">
        <origin xyz="0.02124 0.00108 -0.00165" rpy="0.0 0.0 0.0"/>
        <geometry>
          <mesh filename="package://rmis/meshes/stl/r_shoulder_link.stl" scale="0.1 0.1 0.1"/>
        </geometry>
        <material name="grey"/>
      </visual>
      <collision name="r_upper_shoulder_collision">
        <origin xyz="0.02124 0.00108 -0.00165" rpy="0.0 0.0 0.0"/>
        <geometry>
          <mesh filename="package://rmis/meshes/stl/r_shoulder_link.stl" scale="0.1 0.1 0.1"/>
        </geometry>
      </collision>
    </link>
    <gazebo reference="r_upper_shoulder_link">
      <material>Gazebo/Grey</material>
    </gazebo>

    <joint name="r_lower_shoulder_upper_link_joint" type="revolute">
      <origin xyz="-0.15786 -0.25015 0.0" rpy="1.57080 0.0 0.0"/> <!-- Mirrored for right side -->
      <parent link="r_upper_shoulder_link"/>
      <child link="r_lower_shoulder_upper_link"/>
      <axis xyz="0.0 0.0 1.0"/>
      <dynamics damping="0.50000" friction="0.1"/>
      <limit lower="-1.57" upper="0.0" effort="1.2" velocity="1.0"/> <!-- Symmetric limits, mirrored for right side -->
    </joint>
    <link name="r_lower_shoulder_upper_link">
      <inertial>
        <origin xyz="0.0 0.0 0.0" rpy="0.0 0.0 0.0"/>
        <mass value="0.01"/>
        <inertia ixx="0.001" ixy="0.0" ixz="0.0" iyy="0.001" iyz="0.0" izz="0.001"/>
      </inertial>
      <visual name="r_lower_shoulder_upper">
        <origin xyz="0.0 0.0 0.0" rpy="0.0 0.0 0.0"/>
        <geometry>
          <box size="0.1 0.1 0.1"/>
        </geometry>
        <material name="grey"/>
      </visual>
      <collision name="r_lower_shoulder_upper_collision">
        <origin xyz="0.0 0.0 0.0" rpy="0.0 0.0 0.0"/>
        <geometry>
          <box size="0.1 0.1 0.1"/>
        </geometry>
      </collision>
    </link>
    <gazebo reference="r_lower_shoulder_upper_link">
      <material>Gazebo/Grey</material>
    </gazebo>

    <joint name="r_lower_shoulder_link_joint" type="fixed">
      <origin xyz="0.01024 -0.62216 -0.27345" rpy="-1.57080 0.0 0.0"/> <!-- Mirrored for right side -->
      <parent link="r_lower_shoulder_upper_link"/>
      <child link="r_lower_shoulder_link"/>
    </joint>
    <link name="r_lower_shoulder_link">
      <inertial>
        <origin xyz="0.0 0.0 0.0" rpy="0.0 0.0 0.0"/>
        <mass value="0.01"/>
        <inertia ixx="0.001" ixy="0.0" ixz="0.0" iyy="0.001" iyz="0.0" izz="0.001"/>
      </inertial>
      <visual name="r_lower_shoulder">
        <origin xyz="0.0 0.0 0.0" rpy="0.0 0.0 0.0"/>
        <geometry>
          <mesh filename="package://rmis/meshes/stl/r_shoulder_joint.stl" scale="0.1 0.1 0.1"/>
        </geometry>
        <material name="grey"/>
      </visual>
      <collision name="r_lower_shoulder_collision">
        <origin xyz="0.0 0.0 0.0" rpy="0.0 0.0 0.0"/>
        <geometry>
          <mesh filename="package://rmis/meshes/stl/r_shoulder_joint.stl" scale="0.1 0.1 0.1"/>
        </geometry>
      </collision>
    </link>
    <gazebo reference="r_lower_shoulder_link">
      <material>Gazebo/Grey</material>
    </gazebo>

    <joint name="r_upper_arm_upper_link_joint" type="revolute">
      <origin xyz="0.0 0.0 0.0" rpy="0.0 0.0 0.0"/>
      <parent link="r_lower_shoulder_link"/>
      <child link="r_upper_arm_upper_link"/>
      <axis xyz="0.0 0.0 1.0"/>
      <dynamics damping="0.50000" friction="0.1"/>
      <limit lower="-1.57" upper="1.57" effort="1.2" velocity="1.0"/> <!-- Improvement #3 -->
    </joint>
    <link name="r_upper_arm_upper_link">
      <inertial>
        <origin xyz="0.0 0.0 0.0" rpy="0.0 0.0 0.0"/>
        <mass value="0.01"/>
        <inertia ixx="0.001" ixy="0.0" ixz="0.0" iyy="0.001" iyz="0.0" izz="0.001"/>
      </inertial>
      <visual name="r_upper_arm_upper">
        <origin xyz="0.0 0.0 0.0" rpy="0.0 0.0 0.0"/>
        <geometry>
          <mesh filename="package://rmis/meshes/stl/r_upper_arm_link.stl" scale="0.1 0.1 0.1"/>
        </geometry>
        <material name="grey"/>
      </visual>
      <collision name="r_upper_arm_upper_collision">
        <origin xyz="0.0 0.0 0.0" rpy="0.0 0.0 0.0"/>
        <geometry>
          <mesh filename="package://rmis/meshes/stl/r_upper_arm_link.stl" scale="0.1 0.1 0.1"/>
        </geometry>
      </collision>
    </link>
    <gazebo reference="r_upper_arm_upper_link">
      <material>Gazebo/Grey</material>
    </gazebo>

    <joint name="r_upper_arm_lower_link_joint" type="revolute">
      <origin xyz="0.0 -0.3 0.0" rpy="0.0 0.0 0.0"/> <!-- Mirrored for right side -->
      <parent link="r_upper_arm_upper_link"/>
      <child link="r_upper_arm_lower_link"/>
      <axis xyz="0.0 0.0 1.0"/>
      <dynamics damping="0.50000" friction="0.1"/>
      <limit lower="-1.57" upper="1.57" effort="1.2" velocity="1.0"/> <!-- Improvement #3 -->
    </joint>
    <link name="r_upper_arm_lower_link">
      <inertial>
        <origin xyz="0.0 0.0 0.0" rpy="0.0 0.0 0.0"/>
        <mass value="0.01"/>
        <inertia ixx="0.001" ixy="0.0" ixz="0.0" iyy="0.001" iyz="0.0" izz="0.001"/>
      </inertial>
      <visual name="r_upper_arm_lower">
        <origin xyz="0.0 0.0 0.0" rpy="0.0 0.0 0.0"/>
        <geometry>
          <mesh filename="package://rmis/meshes/stl/r_upper_arm_joint.stl" scale="0.1 0.1 0.1"/>
        </geometry>
        <material name="grey"/>
      </visual>
      <collision name="r_upper_arm_lower_collision">
        <origin xyz="0.0 0.0 0.0" rpy="0.0 0.0 0.0"/>
        <geometry>
          <mesh filename="package://rmis/meshes/stl/r_upper_arm_joint.stl" scale="0.1 0.1 0.1"/>
        </geometry>
      </collision>
    </link>
    <gazebo reference="r_upper_arm_lower_link">
      <material>Gazebo/Grey</material>
    </gazebo>

    <joint name="r_lower_arm_upper_link_joint" type="revolute">
      <origin xyz="0.0 -0.3 0.0" rpy="0.0 0.0 0.0"/> <!-- Mirrored for right side -->
      <parent link="r_upper_arm_lower_link"/>
      <child link="r_lower_arm_upper_link"/>
      <axis xyz="0.0 0.0 1.0"/>
      <dynamics damping="0.50000" friction="0.1"/>
      <limit lower="-1.57" upper="1.57" effort="1.2" velocity="1.0"/> <!-- Improvement #3 -->
    </joint>
    <link name="r_lower_arm_upper_link">
      <inertial>
        <origin xyz="0.0 0.0 0.0" rpy="0.0 0.0 0.0"/>
        <mass value="0.01"/>
        <inertia ixx="0.001" ixy="0.0" ixz="0.0" iyy="0.001" iyz="0.0" izz="0.001"/>
      </inertial>
      <visual name="r_lower_arm_upper">
        <origin xyz="0.0 0.0 0.0" rpy="0.0 0.0 0.0"/>
        <geometry>
          <mesh filename="package://rmis/meshes/stl/r_lower_arm_link.stl" scale="0.1 0.1 0.1"/>
        </geometry>
        <material name="grey"/>
      </visual>
      <collision name="r_lower_arm_upper_collision">
        <origin xyz="0.0 0.0 0.0" rpy="0.0 0.0 0.0"/>
        <geometry>
          <mesh filename="package://rmis/meshes/stl/r_lower_arm_link.stl" scale="0.1 0.1 0.1"/>
        </geometry>
      </collision>
    </link>
    <gazebo reference="r_lower_arm_upper_link">
      <material>Gazebo/Grey</material>
    </gazebo>

    <joint name="r_lower_arm_lower_link_joint" type="revolute">
      <origin xyz="0.0 -0.3 0.0" rpy="0.0 0.0 0.0"/> <!-- Mirrored for right side -->
      <parent link="r_lower_arm_upper_link"/>
      <child link="r_lower_arm_lower_link"/>
      <axis xyz="0.0 0.0 1.0"/>
      <dynamics damping="0.50000" friction="0.1"/>
      <limit lower="-1.57" upper="1.57" effort="1.2" velocity="1.0"/> <!-- Improvement #3 -->
    </joint>
    <link name="r_lower_arm_lower_link">
      <inertial>
        <origin xyz="0.0 0.0 0.0" rpy="0.0 0.0 0.0"/>
        <mass value="0.01"/>
        <inertia ixx="0.001" ixy="0.0" ixz="0.0" iyy="0.001" iyz="0.0" izz="0.001"/>
      </inertial>
      <visual name="r_lower_arm_lower">
        <origin xyz="0.0 0.0 0.0" rpy="0.0 0.0 0.0"/>
        <geometry>
          <mesh filename="package://rmis/meshes/stl/r_lower_arm_joint.stl" scale="0.1 0.1 0.1"/>
        </geometry>
        <material name="grey"/>
      </visual>
      <collision name="r_lower_arm_lower_collision">
        <origin xyz="0.0 0.0 0.0" rpy="0.0 0.0 0.0"/>
        <geometry>
          <mesh filename="package://rmis/meshes/stl/r_lower_arm_joint.stl" scale="0.1 0.1 0.1"/>
        </geometry>
      </collision>
    </link>
    <gazebo reference="r_lower_arm_lower_link">
      <material>Gazebo/Grey</material>
    </gazebo>

    <joint name="r_hand_link_joint" type="fixed">
      <origin xyz="0.0 -0.2 0.0" rpy="0.0 0.0 0.0"/> <!-- Mirrored for right side -->
      <parent link="r_lower_arm_lower_link"/>
      <child link="r_hand_link"/>
    </joint>
    <link name="r_hand_link">
      <inertial>
        <origin xyz="0.0 0.0 0.0" rpy="0.0 0.0 0.0"/>
        <mass value="0.01"/>
        <inertia ixx="0.001" ixy="0.0" ixz="0.0" iyy="0.001" iyz="0.0" izz="0.001"/>
      </inertial>
      <visual name="r_hand">
        <origin xyz="0.0 0.0 0.0" rpy="0.0 0.0 0.0"/>
        <geometry>
          <mesh filename="package://rmis/meshes/stl/r_hand_link.stl" scale="0.1 0.1 0.1"/>
        </geometry>
        <material name="grey"/>
      </visual>
      <collision name="r_hand_collision">
        <origin xyz="0.0 0.0 0.0" rpy="0.0 0.0 0.0"/>
        <geometry>
          <mesh filename="package://rmis/meshes/stl/r_hand_link.stl" scale="0.1 0.1 0.1"/>
        </geometry>
      </collision>
    </link>
    <gazebo reference="r_hand_link">
      <material>Gazebo/Grey</material>
    </gazebo>

<!-- IMU Sensor Plugin (Improvement #7) -->
    <gazebo reference="imu_link">
      <sensor name="imu_sensor" type="imu">
        <pose>0.0 0.0 0.0 0.0 0.0 0.0</pose>
        <imu>
          <noise>
            <type>gaussian</type>
            <rate>
              <mean>0.0</mean>
              <stddev>0.0002</stddev>
            </rate>
            <accel>
              <mean>0.0</mean>
              <stddev>0.0005</stddev>
            </accel>
          </noise>
        </imu>
        <plugin name="imu_plugin" filename="libgazebo_ros_imu_sensor.so">
          <ros>
            <namespace>/rmis</namespace>
            <remapping>~/out:=imu/data</remapping>
          </ros>
          <frame_name>imu_link</frame_name>
          <update_rate>100</update_rate>
        </plugin>
      </sensor>
    </gazebo>

    <!-- Gazebo Control Plugin (Improvement #9) -->
    <gazebo>
      <plugin name="gazebo_ros_control" filename="libgazebo_ros_control.so">
        <ros>
          <namespace>/rmis</namespace>
        </ros>
        <robotNamespace>/rmis</robotNamespace>
        <controlPeriod>0.001</controlPeriod>
        <robotSimType>gazebo_ros_control/DefaultRobotHWSim</robotSimType>
      </plugin>
    </gazebo>

  </robot>
