<robot name="rmis_robot" version="1.0">
  <joint name="head_link_k_joint" type="revolute">
    <dynamics damping="5.00000"/>
    <limit lower="-3.14000" upper="3.14000" effort="0.85000" velocity="6.30000"/>
    <origin rpy="0.00000 -1.57080 0.00000" xyz="-19.46497 -2.05624 35.79721"/>
    <parent link="neck_link_k"/>
    <child link="head_link_k"/>
    <axis xyz="0.00000 0.00000 1.00000"/>
  </joint>
  <joint name="l_ankle_link_k_joint" type="revolute">
    <dynamics damping="5.00000"/>
    <limit lower="-3.14000" upper="3.14000" effort="0.85000" velocity="6.30000"/>
    <origin rpy="-0.00000 -0.00000 0.00000" xyz="-66.90888 -0.02077 -0.09073"/>
    <parent link="l_lower_leg_link_k"/>
    <child link="l_ankle_link_k"/>
    <axis xyz="0.00000 0.00000 1.00000"/>
  </joint>
  <joint name="l_arm_link_k1_joint" type="revolute">
    <dynamics damping="5.00000"/>
    <limit lower="-3.14000" upper="3.14000" effort="0.85000" velocity="6.30000"/>
    <origin rpy="1.57080 -0.00000 3.14159" xyz="0.52979 82.22321 -18.24224"/>
    <parent link="l_shoulder_child_link_k"/>
    <child link="l_arm_link_k1"/>
    <axis xyz="0.00000 0.00000 1.00000"/>
  </joint>
  <joint name="l_arm_link_k2_joint" type="revolute">
    <dynamics damping="5.00000"/>
    <limit lower="-3.14000" upper="3.14000" effort="0.85000" velocity="6.30000"/>
    <origin rpy="-0.00000 1.57080 0.00000" xyz="20.58876 0.13071 35.95849"/>
    <parent link="l_arm_link_k1"/>
    <child link="l_arm_link_k2"/>
    <axis xyz="0.00000 0.00000 1.00000"/>
  </joint>
  <joint name="l_hand_link_k_joint" type="revolute">
    <dynamics damping="5.00000"/>
    <limit lower="-3.14000" upper="3.14000" effort="0.85000" velocity="6.30000"/>
    <origin rpy="-1.57080 1.57080 0.00000" xyz="-68.90010 27.15716 -22.74708"/>
    <parent link="l_arm_link_k2"/>
    <child link="l_hand_link_k"/>
    <axis xyz="0.00000 0.00000 1.00000"/>
  </joint>
  <joint name="l_hip_link_k_joint" type="revolute">
    <dynamics damping="5.00000"/>
    <limit lower="-3.14000" upper="3.14000" effort="0.85000" velocity="6.30000"/>
    <origin rpy="1.57080 -0.00000 -3.14159" xyz="-9.85686 32.56039 24.17409"/>
    <parent link="l_leg_base_link_k"/>
    <child link="l_hip_link_k"/>
    <axis xyz="0.00000 0.00000 1.00000"/>
  </joint>
  <joint name="l_leg_base_link_k_joint" type="revolute">
    <dynamics damping="5.00000"/>
    <limit lower="-3.14000" upper="3.14000" effort="0.85000" velocity="6.30000"/>
    <origin rpy="-3.14159 0.00000 -3.09779" xyz="-48.34199 -18.27487 -131.41250"/>
    <parent link="root_link_k"/>
    <child link="l_leg_base_link_k"/>
    <axis xyz="0.00000 0.00000 1.00000"/>
  </joint>
  <joint name="l_lower_leg_link_k_joint" type="revolute">
    <dynamics damping="5.00000"/>
    <limit lower="-3.14000" upper="3.14000" effort="0.85000" velocity="6.30000"/>
    <origin rpy="0.00000 0.00000 -0.00000" xyz="-66.85407 0.06718 -1.14178"/>
    <parent link="l_upper_leg_link_k"/>
    <child link="l_lower_leg_link_k"/>
    <axis xyz="0.00000 0.00000 1.00000"/>
  </joint>
  <joint name="l_shoulder_base_link_k_joint" type="revolute">
    <dynamics damping="5.00000"/>
    <limit lower="-3.14000" upper="3.14000" effort="0.85000" velocity="6.30000"/>
    <origin rpy="0.00000 -1.57080 0.00000" xyz="-97.63426 -11.24756 51.72586"/>
    <parent link="root_link_k"/>
    <child link="l_shoulder_base_link_k"/>
    <axis xyz="0.00000 0.00000 1.00000"/>
  </joint>
  <joint name="l_shoulder_child_link_k_joint" type="revolute">
    <dynamics damping="5.00000"/>
    <limit lower="-3.14000" upper="3.14000" effort="0.85000" velocity="6.30000"/>
    <origin rpy="-1.57080 1.57080 0.00000" xyz="0.91104 22.00416 35.45252"/>
    <parent link="l_shoulder_base_link_k"/>
    <child link="l_shoulder_child_link_k"/>
    <axis xyz="0.00000 0.00000 1.00000"/>
  </joint>
  <joint name="l_upper_leg_link_k_joint" type="revolute">
    <dynamics damping="5.00000"/>
    <limit lower="-3.14000" upper="3.14000" effort="0.85000" velocity="6.30000"/>
    <origin rpy="1.57080 0.00000 -1.57080" xyz="-32.91063 45.17123 -29.68048"/>
    <parent link="l_hip_link_k"/>
    <child link="l_upper_leg_link_k"/>
    <axis xyz="0.00000 0.00000 1.00000"/>
  </joint>
  <joint name="neck_link_k_joint" type="revolute">
    <dynamics damping="5.00000"/>
    <limit lower="-3.14000" upper="3.14000" effort="0.85000" velocity="6.30000"/>
    <origin rpy="0.00000 0.00000 0.00000" xyz="0.00000 -0.00000 83.06138"/>
    <parent link="root_link_k"/>
    <child link="neck_link_k"/>
    <axis xyz="0.00000 0.00000 1.00000"/>
  </joint>
  <joint name="r_ankle_link_k_joint" type="revolute">
    <dynamics damping="5.00000"/>
    <limit lower="-3.14000" upper="3.14000" effort="0.85000" velocity="6.30000"/>
    <origin rpy="-0.00000 -0.00000 0.00000" xyz="67.37613 -0.01323 -0.03973"/>
    <parent link="r_lower_leg_link_k"/>
    <child link="r_ankle_link_k"/>
    <axis xyz="0.00000 0.00000 1.00000"/>
  </joint>
  <joint name="r_arm_link_k1_joint" type="revolute">
    <dynamics damping="5.00000"/>
    <limit lower="-3.14000" upper="3.14000" effort="0.85000" velocity="6.30000"/>
    <origin rpy="-1.57080 0.00000 -0.00000" xyz="-0.22886 82.21970 -16.19683"/>
    <parent link="r_shoulder_child_link_k"/>
    <child link="r_arm_link_k1"/>
    <axis xyz="0.00000 0.00000 1.00000"/>
  </joint>
  <joint name="r_arm_link_k2_joint" type="revolute">
    <dynamics damping="5.00000"/>
    <limit lower="-3.14000" upper="3.14000" effort="0.85000" velocity="6.30000"/>
    <origin rpy="-2.28313 -1.57080 -0.85846" xyz="18.95558 0.17086 35.89349"/>
    <parent link="r_arm_link_k1"/>
    <child link="r_arm_link_k2"/>
    <axis xyz="0.00000 0.00000 1.00000"/>
  </joint>
  <joint name="r_hand_link_k_joint" type="revolute">
    <dynamics damping="5.00000"/>
    <limit lower="-3.14000" upper="3.14000" effort="0.85000" velocity="6.30000"/>
    <origin rpy="-1.57080 -1.57080 0.00000" xyz="68.59900 25.65830 -21.54085"/>
    <parent link="r_arm_link_k2"/>
    <child link="r_hand_link_k"/>
    <axis xyz="0.00000 0.00000 1.00000"/>
  </joint>
  <joint name="r_hip_link_k_joint" type="revolute">
    <dynamics damping="5.00000"/>
    <limit lower="-3.14000" upper="3.14000" effort="0.85000" velocity="6.30000"/>
    <origin rpy="1.57080 0.00000 0.00000" xyz="-9.72866 -33.20288 24.18766"/>
    <parent link="r_leg_base_link_k"/>
    <child link="r_hip_link_k"/>
    <axis xyz="0.00000 0.00000 1.00000"/>
  </joint>
  <joint name="r_leg_base_link_k_joint" type="revolute">
    <dynamics damping="5.00000"/>
    <limit lower="-3.14000" upper="3.14000" effort="0.85000" velocity="6.30000"/>
    <origin rpy="3.14159 0.00000 0.00000" xyz="48.64802 -18.52139 -131.39921"/>
    <parent link="root_link_k"/>
    <child link="r_leg_base_link_k"/>
    <axis xyz="0.00000 0.00000 1.00000"/>
  </joint>
  <joint name="r_lower_leg_link_k_joint" type="revolute">
    <dynamics damping="5.00000"/>
    <limit lower="-3.14000" upper="3.14000" effort="0.85000" velocity="6.30000"/>
    <origin rpy="-0.00000 0.00000 -0.01530" xyz="66.92873 -0.84708 -0.12632"/>
    <parent link="r_upper_leg_link_k"/>
    <child link="r_lower_leg_link_k"/>
    <axis xyz="0.00000 0.00000 1.00000"/>
  </joint>
  <joint name="r_shoulder_base_link_k_joint" type="revolute">
    <dynamics damping="5.00000"/>
    <limit lower="-3.14000" upper="3.14000" effort="0.85000" velocity="6.30000"/>
    <origin rpy="-0.00000 1.57080 0.00000" xyz="94.01596 -11.07213 51.94397"/>
    <parent link="root_link_k"/>
    <child link="r_shoulder_base_link_k"/>
    <axis xyz="0.00000 0.00000 1.00000"/>
  </joint>
  <joint name="r_shoulder_child_link_k_joint" type="revolute">
    <dynamics damping="5.00000"/>
    <limit lower="-3.14000" upper="3.14000" effort="0.85000" velocity="6.30000"/>
    <origin rpy="-1.57080 -1.57080 0.00000" xyz="-0.69766 20.14315 39.18026"/>
    <parent link="r_shoulder_base_link_k"/>
    <child link="r_shoulder_child_link_k"/>
    <axis xyz="0.00000 0.00000 1.00000"/>
  </joint>
  <joint name="r_upper_leg_link_k_joint" type="revolute">
    <dynamics damping="5.00000"/>
    <limit lower="-3.14000" upper="3.14000" effort="0.85000" velocity="6.30000"/>
    <origin rpy="1.57080 0.00000 1.57080" xyz="31.79766 45.01670 -30.11760"/>
    <parent link="r_hip_link_k"/>
    <child link="r_upper_leg_link_k"/>
    <axis xyz="0.00000 0.00000 1.00000"/>
  </joint>
  <link name="head_link_k">
    <visual name="head_joint">
      <origin rpy="-1.57080 -1.57080 0.00000" xyz="22.93982 43.20002 -19.46497"/>
      <material name="white">
        <color rgba="1 1 1 1"/>
      </material>
      <geometry>
        <mesh filename="file:///home/enesisaoglu/rmis_ws/src/rmis_description/meshes/dae/27-1a.001.dae" scale="1.00000 1.00000 1.00000"/>
      </geometry>
    </visual>
  </link>
  <link name="l_ankle_link_k">
    <visual name="l_ankle_joint">
      <origin rpy="1.57080 1.57080 0.00000" xyz="-30.10730 0.15002 -18.76106"/>
      <material name="white">
        <color rgba="1 1 1 1"/>
      </material>
      <geometry>
        <mesh filename="file:///home/enesisaoglu/rmis_ws/src/rmis_description/meshes/dae/u_bracket.003.dae" scale="1.00000 1.00000 1.00000"/>
      </geometry>
    </visual>
    <visual name="l_feet_link">
      <origin rpy="1.57080 -0.00000 1.57080" xyz="-17.76954 -1.09226 -19.15250"/>
      <material name="white">
        <color rgba="1 1 1 1"/>
      </material>
      <geometry>
        <mesh filename="file:///home/enesisaoglu/rmis_ws/src/rmis_description/meshes/dae/Cube.001.dae" scale="0.77000 0.81000 1.00000"/>
      </geometry>
    </visual>
  </link>
  <link name="l_arm_link_k1">
    <visual name="l_arm_joint">
      <origin rpy="1.57080 0.00000 0.00000" xyz="0.28258 0.50026 5.98672"/>
      <material name="white">
        <color rgba="1 1 1 1"/>
      </material>
      <geometry>
        <mesh filename="file:///home/enesisaoglu/rmis_ws/src/rmis_description/meshes/dae/u_bracket.015.dae" scale="1.00000 1.00000 1.00000"/>
      </geometry>
    </visual>
  </link>
  <link name="l_arm_link_k2">
    <visual name="l_arm_link">
      <origin rpy="-3.14159 -1.57080 0.00000" xyz="-68.72556 2.26477 -5.82007"/>
      <material name="white">
        <color rgba="1 1 1 1"/>
      </material>
      <geometry>
        <mesh filename="file:///home/enesisaoglu/rmis_ws/src/rmis_description/meshes/dae/Cube.019.dae" scale="2.00000 18.36721 18.36721"/>
      </geometry>
    </visual>
  </link>
  <link name="l_hand_link_k">
    <visual name="l_hand_joint">
      <origin rpy="-3.14159 0.00000 0.47600" xyz="-0.31551 -0.17459 -12.99447"/>
      <material name="white">
        <color rgba="1 1 1 1"/>
      </material>
      <geometry>
        <mesh filename="file:///home/enesisaoglu/rmis_ws/src/rmis_description/meshes/dae/offset_bracket.001.dae" scale="1.00000 1.00000 1.00000"/>
      </geometry>
    </visual>
  </link>
  <link name="l_hip_link_k">
    <visual name="l_hip_joint">
      <origin rpy="-3.14159 -1.57080 0.00000" xyz="0.08015 30.04157 -20.11585"/>
      <material name="white">
        <color rgba="1 1 1 1"/>
      </material>
      <geometry>
        <mesh filename="file:///home/enesisaoglu/rmis_ws/src/rmis_description/meshes/dae/u_bracket.004.dae" scale="1.00000 1.00000 1.00000"/>
      </geometry>
    </visual>
    <visual name="l_upper_leg_link">
      <origin rpy="-2.98019 -1.57080 1.40939" xyz="-38.81696 45.14157 -29.68406"/>
      <material name="white">
        <color rgba="1 1 1 1"/>
      </material>
      <geometry>
        <mesh filename="file:///home/enesisaoglu/rmis_ws/src/rmis_description/meshes/dae/Hub_torque.dae" scale="1.00000 1.00000 1.00000"/>
      </geometry>
    </visual>
  </link>
  <link name="l_leg_base_link_k">
    <visual name="l_hip_link">
      <origin rpy="3.14159 -0.00000 0.00000" xyz="-9.83987 38.47630 11.55820"/>
      <material name="white">
        <color rgba="1 1 1 1"/>
      </material>
      <geometry>
        <mesh filename="file:///home/enesisaoglu/rmis_ws/src/rmis_description/meshes/dae/Hub_torque.008.dae" scale="1.00000 1.00000 1.00000"/>
      </geometry>
    </visual>
  </link>
  <link name="l_lower_leg_link_k">
    <visual name="l_ankle_link">
      <origin rpy="0.00000 1.57080 0.00000" xyz="-69.40820 1.23432 -39.65553"/>
      <material name="white">
        <color rgba="1 1 1 1"/>
      </material>
      <geometry>
        <mesh filename="file:///home/enesisaoglu/rmis_ws/src/rmis_description/meshes/dae/Cube.017.dae" scale="2.00000 9.66935 9.66936"/>
      </geometry>
    </visual>
    <visual name="l_lower_leg_joint">
      <origin rpy="1.57080 1.57080 0.00000" xyz="-30.01623 0.12925 -18.85181"/>
      <material name="white">
        <color rgba="1 1 1 1"/>
      </material>
      <geometry>
        <mesh filename="file:///home/enesisaoglu/rmis_ws/src/rmis_description/meshes/dae/u_bracket.001.dae" scale="1.00000 1.00000 1.00000"/>
      </geometry>
    </visual>
  </link>
  <link name="l_shoulder_base_link_k">
    <visual name="l_shoulder_joint">
      <origin rpy="1.57080 -0.00000 1.57080" xyz="0.69714 0.05622 5.62769"/>
      <material name="white">
        <color rgba="1 1 1 1"/>
      </material>
      <geometry>
        <mesh filename="file:///home/enesisaoglu/rmis_ws/src/rmis_description/meshes/dae/u_bracket.011.dae" scale="1.00000 1.00000 1.00000"/>
      </geometry>
    </visual>
  </link>
  <link name="l_shoulder_child_link_k">
    <visual name="l_shoulder_link">
      <origin rpy="-1.57080 0.00000 -1.57080" xyz="-0.00134 0.04804 3.99708"/>
      <material name="white">
        <color rgba="1 1 1 1"/>
      </material>
      <geometry>
        <mesh filename="file:///home/enesisaoglu/rmis_ws/src/rmis_description/meshes/dae/Hub_torque.020.dae" scale="1.00000 1.00000 1.00000"/>
      </geometry>
    </visual>
  </link>
  <link name="l_upper_leg_link_k">
    <visual name="l_lower_leg_link">
      <origin rpy="0.00000 1.57080 0.00000" xyz="-69.26234 1.30150 -40.79734"/>
      <material name="white">
        <color rgba="1 1 1 1"/>
      </material>
      <geometry>
        <mesh filename="file:///home/enesisaoglu/rmis_ws/src/rmis_description/meshes/dae/Cube.005.dae" scale="2.00000 9.66936 9.66936"/>
      </geometry>
    </visual>
    <visual name="l_upper_leg_joint">
      <origin rpy="-1.57080 0.00000 -1.57080" xyz="0.12963 -0.00358 -47.96052"/>
      <material name="white">
        <color rgba="1 1 1 1"/>
      </material>
      <geometry>
        <mesh filename="file:///home/enesisaoglu/rmis_ws/src/rmis_description/meshes/dae/Hub_torque.036.dae" scale="1.00000 1.00000 1.00000"/>
      </geometry>
    </visual>
  </link>
  <link name="neck_link_k">
    <visual name="neck_joint">
      <origin rpy="-1.57080 -1.57080 0.00000" xyz="-3.98343 -8.30060 45.70511"/>
      <material name="white">
        <color rgba="1 1 1 1"/>
      </material>
      <geometry>
        <mesh filename="file:///home/enesisaoglu/rmis_ws/src/rmis_description/meshes/dae/Hub_torque.002.dae" scale="1.00000 1.00000 1.00000"/>
      </geometry>
    </visual>
  </link>
  <link name="r_ankle_link_k">
    <visual name="r_ankle_joint">
      <origin rpy="1.58417 -1.57080 0.00000" xyz="29.71100 0.47074 -18.72772"/>
      <material name="white">
        <color rgba="1 1 1 1"/>
      </material>
      <geometry>
        <mesh filename="file:///home/enesisaoglu/rmis_ws/src/rmis_description/meshes/dae/u_bracket.012.dae" scale="1.00000 1.00000 1.00000"/>
      </geometry>
    </visual>
    <visual name="r_feet_joint_link">
      <origin rpy="-1.57080 0.00000 1.58417" xyz="17.39096 -0.93638 -19.62160"/>
      <material name="white">
        <color rgba="1 1 1 1"/>
      </material>
      <geometry>
        <mesh filename="file:///home/enesisaoglu/rmis_ws/src/rmis_description/meshes/dae/Cube.029.dae" scale="0.77000 0.81000 1.00000"/>
      </geometry>
    </visual>
  </link>
  <link name="r_arm_link_k1">
    <visual name="r_arm_joint">
      <origin rpy="1.57080 -0.00000 3.14159" xyz="0.13979 -0.13156 6.04999"/>
      <material name="white">
        <color rgba="1 1 1 1"/>
      </material>
      <geometry>
        <mesh filename="file:///home/enesisaoglu/rmis_ws/src/rmis_description/meshes/dae/u_bracket.014.dae" scale="1.00000 1.00000 1.00000"/>
      </geometry>
    </visual>
  </link>
  <link name="r_arm_link_k2">
    <visual name="r_arm_link">
      <origin rpy="-0.00000 -1.57080 0.00000" xyz="92.06708 5.14913 -6.69152"/>
      <material name="white">
        <color rgba="1 1 1 1"/>
      </material>
      <geometry>
        <mesh filename="file:///home/enesisaoglu/rmis_ws/src/rmis_description/meshes/dae/Cube.021.dae" scale="2.00000 18.36721 18.36721"/>
      </geometry>
    </visual>
  </link>
  <link name="r_hand_link_k">
    <visual name="r_hand_joint">
      <origin rpy="-0.00000 -0.00000 2.68714" xyz="0.38062 0.19957 -36.13983"/>
      <material name="white">
        <color rgba="1 1 1 1"/>
      </material>
      <geometry>
        <mesh filename="file:///home/enesisaoglu/rmis_ws/src/rmis_description/meshes/dae/offset_bracket.003.dae" scale="1.00000 1.00000 1.00000"/>
      </geometry>
    </visual>
  </link>
  <link name="r_hip_link_k">
    <visual name="r_hip_joint">
      <origin rpy="-3.14159 -1.57080 0.00000" xyz="-0.11002 30.04136 -20.51182"/>
      <material name="white">
        <color rgba="1 1 1 1"/>
      </material>
      <geometry>
        <mesh filename="file:///home/enesisaoglu/rmis_ws/src/rmis_description/meshes/dae/u_bracket.005.dae" scale="1.00000 1.00000 1.00000"/>
      </geometry>
    </visual>
    <visual name="r_upper_leg_link">
      <origin rpy="0.07469 -1.57080 1.49610" xyz="38.78710 32.48986 -30.08003"/>
      <material name="white">
        <color rgba="1 1 1 1"/>
      </material>
      <geometry>
        <mesh filename="file:///home/enesisaoglu/rmis_ws/src/rmis_description/meshes/dae/Hub_torque.011.dae" scale="1.00000 1.00000 1.00000"/>
      </geometry>
    </visual>
  </link>
  <link name="r_leg_base_link_k">
    <visual name="r_hip_link">
      <origin rpy="3.14159 0.00000 3.14159" xyz="9.18341 -38.72283 11.98324"/>
      <material name="white">
        <color rgba="1 1 1 1"/>
      </material>
      <geometry>
        <mesh filename="file:///home/enesisaoglu/rmis_ws/src/rmis_description/meshes/dae/Hub_torque.010.dae" scale="1.00000 1.00000 1.00000"/>
      </geometry>
    </visual>
  </link>
  <link name="r_lower_leg_link_k">
    <visual name="r_ankle_link">
      <origin rpy="3.14159 1.57080 0.00000" xyz="69.48281 1.16536 -39.57115"/>
      <material name="white">
        <color rgba="1 1 1 1"/>
      </material>
      <geometry>
        <mesh filename="file:///home/enesisaoglu/rmis_ws/src/rmis_description/meshes/dae/Cube.023.dae" scale="2.00000 9.66936 9.66936"/>
      </geometry>
    </visual>
    <visual name="r_lower_leg_joint">
      <origin rpy="1.57080 -1.57080 0.00000" xyz="30.09082 0.06028 -18.78420"/>
      <material name="white">
        <color rgba="1 1 1 1"/>
      </material>
      <geometry>
        <mesh filename="file:///home/enesisaoglu/rmis_ws/src/rmis_description/meshes/dae/u_bracket.007.dae" scale="1.00000 1.00000 1.00000"/>
      </geometry>
    </visual>
  </link>
  <link name="r_shoulder_base_link_k">
    <visual name="r_shoulder_joint">
      <origin rpy="1.57080 -0.00000 -1.57080" xyz="-0.47906 -0.12808 9.40137"/>
      <material name="white">
        <color rgba="1 1 1 1"/>
      </material>
      <geometry>
        <mesh filename="file:///home/enesisaoglu/rmis_ws/src/rmis_description/meshes/dae/u_bracket.010.dae" scale="1.00000 1.00000 1.00000"/>
      </geometry>
    </visual>
  </link>
  <link name="r_shoulder_child_link_k">
    <visual name="r_shoulder_link">
      <origin rpy="-1.57080 1.57080 0.00000" xyz="1.23528 -2.24133 -41.31914"/>
      <material name="white">
        <color rgba="1 1 1 1"/>
      </material>
      <geometry>
        <mesh filename="file:///home/enesisaoglu/rmis_ws/src/rmis_description/meshes/dae/Cube.007.dae" scale="2.00000 9.66936 9.66936"/>
      </geometry>
    </visual>
  </link>
  <link name="r_upper_leg_link_k">
    <visual name="r_lower_leg_link">
      <origin rpy="-3.12629 1.57080 0.00000" xyz="69.42911 0.28015 -39.71424"/>
      <material name="white">
        <color rgba="1 1 1 1"/>
      </material>
      <geometry>
        <mesh filename="file:///home/enesisaoglu/rmis_ws/src/rmis_description/meshes/dae/Cube.008.dae" scale="2.00000 9.66936 9.66936"/>
      </geometry>
    </visual>
    <visual name="r_upper_leg_joint">
      <origin rpy="-1.57080 0.00000 1.55549" xyz="0.02528 0.03719 -46.91214"/>
      <material name="white">
        <color rgba="1 1 1 1"/>
      </material>
      <geometry>
        <mesh filename="file:///home/enesisaoglu/rmis_ws/src/rmis_description/meshes/dae/Hub_torque.035.dae" scale="1.00000 1.00000 1.00000"/>
      </geometry>
    </visual>
  </link>
  <link name="root_link_k">
    <visual name="upper_body_link">
      <origin rpy="0.00000 0.00000 0.00000" xyz="0.00000 -0.00000 -0.00003"/>
      <material name="white">
        <color rgba="1 1 1 1"/>
      </material>
      <geometry>
        <mesh filename="file:///home/enesisaoglu/rmis_ws/src/rmis_description/meshes/dae/Cube.020.dae" scale="1.01000 1.00000 1.00000"/>
      </geometry>
    </visual>
  </link>
</robot>